Workbook

Sheet APR
A1: APRIL MONTH RAKE LOADING DATA
A2: SL NO | B2: LOADING DATE | C2: RAKE NO | D2: PRIORTY NUMBER | E2: R.R NUMBER | F2: NO OF WAGON | G2: NET WEIGHT | H2: UNDER LOAD WT | I2: OVER LOAD WT | J2: O/L WAGON | K2: O/L CHARGE | L2: DETENTION HOURS | M2: DETENTION CHARGES | N2: SHUNTING HOURS | O2: SHUNTING CHARGES | P2: PILOT HOURS | Q2: PILOT CHARGES | R2: PCLA | S2: GST 5% | T2: TOTAL AMOUNT RS
A3: 1 | B3: 01.04.20 | C3: 240 | D3: 1 | E3: 141000012 | F3: 59 | G3: 3580.84 | H3: 255.98 | I3: 0 | J3: 1 | K3: 5000 | L3: 1 | M3: 17700 | N3: 0 | Q3: 0 | R3: =K3+M3+Q3 -> 22700 | S3: =R3*5% -> 1135 | T3: =R3+S3 -> 23835
A4: 2 | B4: 01.04.20 | C4: 241 | D4: 2 | E4: 151000006 | F4: 59 | G4: 3577.11 | H4: 257.39 | I4: 0 | J4: 0 | K4: 0 | L4: 0 | M4: 0 | N4: 0 | Q4: 0 | R4: =K4+M4+Q4 -> 0 | S4: =R4*5% -> 0 | T4: =R4+S4 -> 0
A5: 3 | B5: 02.04.20 | C5: 242 | D5: 3 | E5: 161000224 | F5: 59 | G5: 3626.31 | H5: 208.69 | I5: 0 | J5: 0 | K5: 0 | L5: 0 | M5: 0 | N5: 0 | Q5: 0 | R5: =K5+M5+Q5 -> 0 | S5: =R5*5% -> 0 | T5: =R5+S5 -> 0
A6: 4 | B6: 03.04.20 | C6: 243 | D6: 4 | E6: 161000225 | F6: 59 | G6: 3652.42 | H6: 188.62 | I6: 7.04 | J6: 3 | K6: 15000 | L6: 1 | M6: 8850 | N6: 0 | Q6: 0 | R6: =K6+M6+Q6 -> 23850 | S6: =R6*5% -> 1192.5 | T6: =R6+S6 -> 25042.5
A7: 5 | B7: 04.04.20 | C7: 244 | D7: 5 | E7: 161000226 | F7: 59 | G7: 3638.81 | H7: 190.76 | I7: 0.12291667 | J7: 1 | K7: 5000 | L7: 1 | M7: 8850 | N7: 0 | Q7: 0 | R7: =K7+M7+Q7 -> 13850 | S7: =R7*5% -> 692.5 | T7: =R7+S7 -> 14542.5
A8: 6 | B8: 05.04.20 | C8: 245 | D8: 6 | E8: 161000227 | F8: 59 | G8: 3676.01 | H8: 168.62 | I8: 9.63 | J8: 5 | K8: 25000 | L8: 1 | M8: 8850 | N8: 0 | Q8: 0 | R8: =K8+M8+Q8 -> 33850 | S8: =R8*5% -> 1692.5 | T8: =R8+S8 -> 35542.5
E9: TOTAL | F9: =SUM(F3:F8) -> 354 | G9: =SUM(G3:G8) -> 21751.5 | H9: =SUM(H3:H8) -> 1270.06 | I9: 16.79 | J9: =SUM(J3:J8) -> 10 | K9: =SUM(K3:K8) -> 50000 | L9: =SUM(L3:L8) -> 4 | M9: =SUM(M3:M8) -> 44250 | N9: =SUM(N3:N8) -> 0 | Q9: =SUM(Q3:Q8) -> 0 | R9: =SUM(R3:R8) -> 94250 | S9: =R9*5% -> 4712.5 | T9: =SUM(T3:T8) -> 98962.5

Sheet MAY
A1: MAY MONTH RAKE LOADING DATA
A2: SL NO | B2: LOADING DATE | C2: RAKE NO. | D2: PRIORTY NUMBER | E2: R.R NUMBER | F2: NO OF WAGON | G2: NET WEIGHT | H2: UNDER LOAD WT | I2: OVER LOAD WT | J2: O/L WAGON | K2: O/L CHARGE | L2: DETENTION HOURS | M2: DETENTION CHARGES | N2: SHUNTING HOURS | O2: SHUNTING CHARGES | P2: PILOT HOURS | Q2: PILOT CHARGES | R2: PCLA | S2: GST 5% | T2: TOTAL AMOUNT RS
A3: 1 | B3: 05.05.20 | C3: 246 | D3: 7 | E3: 161000228 | F3: 58 | G3: 3616.22 | H3: 150.6 | I3: 5.82 | J3: 3 | K3: 15000 | L3: 1 | M3: 17400 | N3: 0 | Q3: 0 | R3: =K3+M3+Q3 -> 32400 | S3: =R3*5% -> 1620 | T3: =R3+S3 -> 34020
A4: 2 | B4: 06.05.20 | C4: 247 | D4: 8 | E4: 161000229 | F4: 59 | G4: 3665.51 | H4: 175.93 | I4: 6.44 | J4: 4 | K4: 20000 | L4: 1 | M4: 8850 | N4: 0 | Q4: 0 | R4: =K4+M4+Q4 -> 28850 | S4: =R4*5% -> 1442.5 | T4: =R4+S4 -> 30292.5
A5: 3 | B5: 07.05.20 | C5: 248 | D5: 9 | E5: 161000230 | F5: 58 | G5: 3605.24 | H5: 168.27 | I5: 5.51 | J5: 2 | K5: 10000 | L5: 1 | M5: 8850 | N5: 0 | Q5: 0 | R5: =K5+M5+Q5 -> 18850 | S5: =R5*5% -> 942.5 | T5: =R5+S5 -> 19792.5
A6: 4 | B6: 08.05.20 | C6: 249 | D6: 10 | E6: 161000231 | F6: 59 | G6: 3629.81 | H6: 207.63 | I6: 2.44 | J6: 1 | K6: 5000 | L6: 1 | M6: 8850 | N6: 0 | Q6: 0 | R6: =K6+M6+Q6 -> 13850 | S6: =R6*5% -> 692.5 | T6: =R6+S6 -> 14542.5
A7: 5 | B7: 09.05.20 | C7: 250 | D7: 11 | E7: 161000232 | F7: 59 | G7: 3718.04 | H7: 131.46 | I7: 17.5 | J7: 6 | K7: 30000 | L7: 2 | M7: 17700 | N7: 0 | Q7: 0 | R7: =K7+M7+Q7 -> 47700 | S7: =R7*5% -> 2385 | T7: =R7+S7 -> 50085
A8: 6 | B8: 10.05.20 | C8: 251 | D8: 12 | E8: 161000233 | F8: 59 | G8: 3663.03 | H8: 174.63 | I8: 4.66 | J8: 2 | K8: 10000 | L8: 1 | M8: 8850 | N8: 0 | Q8: 0 | R8: =K8+M8+Q8 -> 18850 | S8: =R8*5% -> 942.5 | T8: =R8+S8 -> 19792.5
A9: 7 | B9: 11.05.20 | C9: 252 | D9: 13 | E9: 161000234 | F9: 59 | G9: 3692.01 | H9: 153 | I9: 10.01 | J9: 7 | K9: 35000 | L9: 2 | M9: 17700 | N9: 0 | Q9: 0 | R9: =K9+M9+Q9 -> 52700 | S9: =R9*5% -> 2635 | T9: =R9+S9 -> 55335
A10: 8 | B10: 12.05.20 | C10: 253 | D10: 14 | E10: 161000235 | F10: 57 | G10: 3497.35 | H10: 208.84 | I10: 3.19 | J10: 1 | K10: 5000 | L10: 1 | M10: 8850 | N10: 0 | Q10: 0 | R10: =K10+M10+Q10 -> 13850 | S10: =R10*5% -> 692.5 | T10: =R10+S10 -> 14542.5
A11: 9 | B11: 12.05.20 | C11: 254 | D11: 15 | E11: 161000236 | F11: 58 | G11: 3544.72 | H11: 225.28 | I11: 0 | J11: 0 | K11: 0 | L11: 0 | M11: 0 | N11: 0 | Q11: 0 | R11: =K11+M11+Q11 -> 0 | S11: =R11*5% -> 0 | T11: =R11+S11 -> 0
A12: 10 | B12: 13.05.20 | C12: 255 | D12: 16 | E12: 161000237 | F12: 59 | G12: 3667.02 | H12: 169.64 | I12: 2.66 | J12: 1 | K12: 5000 | L12: 1 | M12: 8850 | N12: 0 | Q12: 0 | R12: =K12+M12+Q12 -> 13850 | S12: =R12*5% -> 692.5 | T12: =R12+S12 -> 14542.5
A13: 11 | B13: 13.05.20 | C13: 256 | D13: 17 | E13: 161000238 | F13: 57 | G13: 3527.54 | H13: 179.81 | I13: 3.35 | J13: 2 | K13: 10000 | L13: 1 | M13: 8850 | N13: 0 | Q13: 0 | R13: =K13+M13+Q13 -> 18850 | S13: =R13*5% -> 942.5 | T13: =R13+S13 -> 19792.5
A14: 12 | B14: 14.05.20 | C14: 257 | D14: 18 | E14: 141000013 | F14: 58 | G14: 3583.83 | H14: 204.37 | I14: 19.2 | J14: 10 | K14: 50000 | L14: 2 | M14: 17400 | N14: 0 | Q14: 0 | R14: =K14+M14+Q14 -> 67400 | S14: =R14*5% -> 3370 | T14: =R14+S14 -> 70770
... A61: 59 | B61: 31.05.20 | C61: 304 | D61: 65 | E61: 161000274 | F61: 57 | G61: 3462.56 | H61: 241.18 | I61: 1.69 | J61: 1 | K61: 5000 | L61: 1 | M61: 8550 | N61: 0 | Q61: 0 | R61: =K61+M61+Q61 -> 13550 | S61: =R61*5% -> 677.5 | T61: =R61+S61 -> 14227.5
E62: TOTAL | G62: =SUM(G3:G61) -> 211501.89 | H62: =SUM(H3:H61) -> 12000.09 | I62: =SUM(I3:I61) -> 335.47 | J62: =SUM(J3:J61) -> 166 | K62: =SUM(K3:K61) -> 830000 | L62: =SUM(L3:L61) -> 58 | M62: =SUM(M3:M61) -> 515700 | N62: =SUM(N3:N61) -> 0 | Q62: =SUM(Q3:Q61) -> 0 | R62: =SUM(R3:R61) -> 1345700 | S62: =SUM(S3:S61) -> 67285 | T62: =SUM(T3:T61) -> 1412985

Sheet JUN
A1: JUNE MONTH RAKE LOADING DATA
A2: SL NO | B2: LOADING DATE | C2: RAKE NO. | D2: PRIORTY NUMBER | E2: R.R NUMBER | F2: NO OF WAGON | G2: NET WEIGHT | H2: UNDER LOAD WT | I2: OVER LOAD WT | J2: O/L WAGON | K2: O/L CHARGE | L2: DETENTION HOURS | M2: DETENTION CHARGES | N2: SHUNTING HOURS | O2: SHUNTING CHARGES | P2: PILOT HOURS | Q2: PILOT CHARGES | R2: PCLA | S2: GST 5% | T2: TOTAL AMOUNT RS
A3: 66 | B3: 01.06.20 | C3: 1 | D3: 66 | E3: 161000275 | F3: 57 | G3: 3468.43 | H3: 236.57 | I3: 0 | J3: 0 | K3: 0 | L3: 0 | M3: 0 | N3: 0 | O3: 0 | P3: 0 | Q3: 0 | R3: =K3+M3+Q3 -> 0 | S3: =R3*5% -> 0 | T3: =R3+S3 -> 0
A4: 67 | B4: 01.06.20 | C4: 2 | D4: 67 | E4: 161000276 | F4: 59 | G4: 3493.51 | H4: 341.49 | I4: 0 | J4: 0 | K4: 0 | L4: 0 | M4: 0 | N4: 0 | O4: 0 | P4: 0 | Q4: 0 | R4: =K4+M4+Q4 -> 0 | S4: =R4*5% -> 0 | T4: =R4+S4 -> 0
A5: 68 | B5: 02.06.20 | C5: 3 | D5: 68 | E5: 161000277 | F5: 58 | G5: 3430.43 | H5: 340.16 | I5: 1.59 | J5: 1 | K5: 5000 | L5: 1 | M5: 8700 | N5: 0 | Q5: 0 | R5: =K5+M5+Q5 -> 13700 | S5: =R5*5% -> 685 | T5: =R5+S5 -> 14385
A6: 69 | B6: 02.06.20 | C6: 4 | D6: 69 | E6: 161000278 | F6: 57 | G6: 3455.96 | H6: 246.73 | I6: 0.69 | J6: 1 | K6: 5000 | L6: 1 | M6: 8550 | N6: 0 | Q6: 0 | R6: =K6+M6+Q6 -> 13550 | S6: =R6*5% -> 677.5 | T6: =R6+S6 -> 14227.5
A7: 70 | B7: 02.06.20 | C7: 5 | D7: 70 | E7: 161000279 | F7: 59 | G7: 3581.21 | H7: 253.79 | I7: 0 | J7: 0 | K7: 0 | L7: 0 | M7: 0 | N7: 0 | Q7: 0 | R7: =K7+M7+Q7 -> 0 | S7: =R7*5% -> 0 | T7: =R7+S7 -> 0
A8: 71 | B8: 02.06.20 | C8: 6 | D8: 71 | E8: 161000280 | F8: 58 | G8: 3426.92 | H8: 340 | I8: 0 | J8: 0 | K8: 0 | L8: 0 | M8: 0 | N8: 0 | Q8: 0 | R8: =K8+M8+Q8 -> 0 | S8: =R8*5% -> 0 | T8: =R8+S8 -> 0
A9: 72 | B9: 03.06.20 | C9: 7 | D9: 72 | E9: 161000281 | F9: 58 | G9: 3315.76 | H9: 322.24 | I9: 0 | J9: 0 | K9: 0 | L9: 0 | M9: 0 | N9: 0 | Q9: 0 | R9: =K9+M9+Q9 -> 0 | S9: =R9*5% -> 0 | T9: =R9+S9 -> 0
A10: 73 | B10: 03.06.20 | C10: 8 | D10: 73 | E10: 161000282 | F10: 58 | G10: 3430.13 | H10: 341.61 | I10: 2.77 | J10: 2 | K10: 10000 | L10: 1 | M10: 8700 | N10: 0 | Q10: 0 | R10: =K10+M10+Q10 -> 18700 | S10: =R10*5% -> 935 | T10: =R10+S10 -> 19635
A11: 74 | B11: 03.06.20 | C11: 9 | D11: 74 | E11: 161000283 | F11: 58 | G11: 3330.12 | H11: 439.5 | I11: 0 | J11: 0 | K11: 0 | L11: 0 | M11: 0 | N11: 0 | Q11: 0 | R11: =K11+M11+Q11 -> 0 | S11: =R11*5% -> 0 | T11: =R11+S11 -> 0
A12: 75 | B12: 04.06.20 | C12: 10 | D12: 75 | E12: 161000284 | F12: 59 | G12: 3455.61 | H12: 379.39 | I12: 0 | J12: 0 | K12: 0 | L12: 0 | M12: 0 | N12: 0 | Q12: 0 | R12: =K12+M12+Q12 -> 0 | S12: =R12*5% -> 0 | T12: =R12+S12 -> 0
A13: 76 | B13: 04.06.20 | C13: 11 | D13: 76 | E13: 161000285 | F13: 58 | G13: 3363.13 | H13: 408.73 | I13: 2.86 | J13: 2 | K13: 10000 | L13: 1 | M13: 8700 | N13: 0 | Q13: 0 | R13: =K13+M13+Q13 -> 18700 | S13: =R13*5% -> 935 | T13: =R13+S13 -> 19635
A14: 77 | B14: 04.06.20 | C14: 12 | D14: 77 | E14: 161000286 | F14: 59 | G14: 3384.12 | H14: 450.87 | I14: 0.99 | J14: 1 | K14: 5000 | L14: 1 | M14: 8850 | N14: 0 | Q14: 0 | R14: =K14+M14+Q14 -> 13850 | S14: =R14*5% -> 692.5 | T14: =R14+S14 -> 14542.5
A15: 78 | B15: 04.06.20 | C15: 13 | D15: 78 | E15: 161000287 | F15: 55 | G15: 3146.57 | H15: 426.43 | I15: 0 | J15: 0 | K15: 0 | L15: 0 | M15: 0 | N15: 0 | Q15: 0 | R15: =K15+M15+Q15 -> 0 | S15: =R15*5% -> 0 | T15: =R15+S15 -> 0
A16: 79 | B16: 05.06.20 | C16: 14 | D16: 79 | E16: 161000288 | F16: 58 | G16: 3385.53 | H16: 386.54 | I16: 3.07 | J16: 2 | K16: 10000 | L16: 1 | M16: 8700 | N16: 0 | Q16: 0 | R16: =K16+M16+Q16 -> 18700 | S16: =R16*5% -> 935 | T16: =R16+S16 -> 19635
... A83: 146 | B83: 28.06.20 | C83: 81 | D83: 146 | E83: 161000355 | F83: 57 | G83: 3409.73 | H83: 296.56 | I83: 1.29 | J83: 1 | K83: 5000 | L83: 1 | M83: 8550 | N83: 0 | Q83: 0 | R83: =K83+M83+Q83 -> 13550 | S83: =R83*5% -> 677.5 | T83: =R83+S83 -> 14227.5
A84: 147 | B84: 28.06.20 | C84: 82 | D84: 147 | E84: 161000356 | F84: 58 | G84: 3496.32 | H84: 273.68 | I84: 0 | J84: 0 | K84: 0 | L84: 0 | M84: 0 | N84: 0 | O84: 0 | P84: 0 | Q84: 0 | R84: =K84+M84+Q84 -> 0 | S84: =R84*5% -> 0 | T84: =R84+S84 -> 0
A85: 148 | B85: 28.06.20 | C85: 83 | D85: 148 | E85: 161000357 | F85: 59 | G85: 3570.13 | H85: 263.27 | I85: 0.4 | J85: 0 | K85: 0 | L85: 0 | M85: 0 | N85: 0 | O85: 0 | P85: 0 | Q85: 0 | R85: =K85+M85+Q85 -> 0 | S85: =R85*5% -> 0 | T85: =R85+S85 -> 0
A86: 149 | B86: 29.06.20 | C86: 84 | D86: 149 | E86: 161000358 | F86: 59 | G86: 3554.42 | H86: 279.58 | I86: 0 | J86: 0 | K86: 0 | L86: 0 | M86: 0 | N86: 0 | O86: 0 | P86: 0 | Q86: 0 | R86: =K86+M86+Q86 -> 0 | S86: =R86*5% -> 0 | T86: =R86+S86 -> 0
A87: 150 | B87: 29.06.20 | C87: 85 | D87: 150 | E87: 161000359 | F87: 59 | G87: 3569.33 | H87: 266.36 | I87: 2.69 | J87: 1 | K87: 5000 | L87: 1 | M87: 8850 | N87: 0 | Q87: 0 | R87: =K87+M87+Q87 -> 13850 | S87: =R87*5% -> 692.5 | T87: =R87+S87 -> 14542.5
A88: 151 | B88: 29.06.20 | C88: 86 | D88: 151 | E88: 161000360 | F88: 59 | G88: 3625.71 | H88: 211.16 | I88: 1.07 | J88: 1 | K88: 5000 | L88: 1 | M88: 8850 | N88: 0 | Q88: 0 | R88: =K88+M88+Q88 -> 13850 | S88: =R88*5% -> 692.5 | T88: =R88+S88 -> 14542.5
A89: 152 | B89: 29.06.20 | C89: 87 | D89: 152 | E89: 161000361 | F89: 58 | G89: 3394.25 | H89: 372.75 | I89: 0 | J89: 0 | K89: 0 | L89: 0 | M89: 0 | N89: 0 | Q89: 0 | R89: =K89+M89+Q89 -> 0 | S89: =R89*5% -> 0 | T89: =R89+S89 -> 0
A90: 153 | B90: 30.06.20 | C90: 88 | D90: 153 | E90: 161000362 | F90: 57 | G90: 3456.33 | H90: 250.15 | I90: 1.4 | J90: 1 | K90: 5000 | L90: 1 | M90: 8550 | N90: 0 | Q90: 0 | R90: =K90+M90+Q90 -> 13550 | S90: =R90*5% -> 677.5 | T90: =R90+S90 -> 14227.5
A91: 154 | B91: 30.06.20 | C91: 89 | D91: 154 | E91: 161000363 | F91: 57 | G91: 3457.64 | H91: 246.36 | I91: 0 | J91: 0 | K91: 0 | L91: 0 | M91: 0 | N91: 0 | O91: 0 | P91: 0 | Q91: 0 | R91: =K91+M91+Q91 -> 0 | S91: =R91*5% -> 0 | T91: =R91+S91 -> 0
A92: 155 | B92: 30.06.20 | C92: 90 | D92: 155 | E92: 161000364 | F92: 59 | G92: 3566.23 | H92: 267.05 | I92: 0.28 | J92: 0 | K92: 0 | L92: 0 | M92: 0 | N92: 0 | O92: 0 | P92: 0 | Q92: 0 | R92: =K92+M92+Q92 -> 0 | S92: =R92*5% -> 0 | T92: =R92+S92 -> 0
A93: 156 | B93: 30.06.20 | C93: 91 | D93: 156 | E93: 161000365 | F93: 58 | G93: 3433.02 | H93: 337.37 | I93: 0.39 | J93: 0 | K93: 0 | L93: 0 | M93: 0 | N93: 0 | O93: 0 | P93: 0 | Q93: 0 | R93: =K93+M93+Q93 -> 0 | S93: =R93*5% -> 0 | T93: =R93+S93 -> 0
E94: TOTAL | F94: =SUM(F3:F93) -> 5315 | G94: =SUM(G3:G93) -> 321122.39 | H94: =SUM(H3:H93) -> 24063.08 | I94: =SUM(I3:I93) -> 286.4 | J94: =SUM(J3:J93) -> 147 | K94: =SUM(K3:K93) -> 735000 | L94: =SUM(L3:L93) -> 53 | M94: =SUM(M3:M93) -> 463200 | ... T94: =SUM(T3:T93) -> 1332135
F95: =G94/C93 -> 3528.8175

Sheet JUL
A1: JULY MONTH RAKE LOADING DATA
A2: SL NO | B2: LOADING DATE | C2: RAKE NO. | D2: PRIORTY NUMBER | E2: R.R NUMBER | F2: NO OF WAGON | G2: NET WEIGHT | H2: UNDER LOAD WT | I2: OVER LOAD WT | J2: O/L WAGON | K2: O/L CHARGE | L2: DETENTION HOURS | M2: DETENTION CHARGES | N2: SHUNTING HOURS | O2: SHUNTING CHARGES | P2: PILOT HOURS | Q2: PILOT CHARGES | R2: PCLA | S2: GST 5% | T2: TOTAL AMOUNT RS
A3: 157 | B3: 01.07.20 | C3: 1 | D3: 157 | E3: 161000366 | F3: 58 | G3: 3474.23 | H3: 237.75 | I3: 0.98 | J3: 0 | K3: 0 | L3: 0 | M3: 0 | N3: 0 | O3: 0 | P3: 0 | Q3: 0 | R3: =K3+M3+Q3 -> 0 | S3: =R3*5% -> 0 | T3: =R3+S3 -> 0
A4: 158 | B4: 01.07.20 | C4: 2 | D4: 158 | E4: 161000367 | F4: 59 | G4: 3536.45 | H4: 237.82 | I4: 2.27 | J4: 0 | K4: 0 | L4: 0 | M4: 0 | N4: 0 | O4: 0 | P4: 0 | Q4: 0 | R4: =K4+M4+Q4 -> 0 | S4: =R4*5% -> 0 | T4: =R4+S4 -> 0
A5: 159 | B5: 02.07.20 | C5: 3 | D5: 159 | E5: 161000368 | F5: 59 | G5: 3507.92 | H5: 267.76 | I5: 0.68 | J5: 0 | K5: 0 | L5: 0 | M5: 0 | N5: 0 | O5: 0 | P5: 0 | Q5: 0 | R5: =K5+M5+Q5 -> 0 | S5: =R5*5% -> 0 | T5: =R5+S5 -> 0
A6: 160 | B6: 02.07.20 | C6: 4 | D6: 160 | E6: 151000012 | F6: 59 | G6: 3486.82 | H6: 294.83 | I6: 6.65 | J6: 2 | K6: 10000 | L6: 1 | M6: 8850 | N6: 0 | Q6: 0 | R6: =K6+M6+Q6 -> 18850 | S6: =R6*5% -> 942.5 | T6: =R6+S6 -> 19792.5
A7: 161 | B7: 02.07.20 | C7: 5 | D7: 161 | E7: 161000369 | F7: 59 | G7: 3479.92 | H7: 301.85 | I7: 6.77 | J7: 1 | K7: 5000 | L7: 1 | M7: 8850 | N7: 0 | Q7: 0 | R7: =K7+M7+Q7 -> 13850 | S7: =R7*5% -> 692.5 | T7: =R7+S7 -> 14542.5
A8: 162 | B8: 03.07.20 | C8: 6 | D8: 162 | E8: 161000370 | F8: 57 | G8: 3441.43 | H8: 209.94 | I8: 3.37 | J8: 1 | K8: 5000 | L8: 1 | M8: 8550 | N8: 0 | Q8: 0 | R8: =K8+M8+Q8 -> 13550 | S8: =R8*5% -> 677.5 | T8: =R8+S8 -> 14227.5
A9: 163 | B9: 03.07.20 | C9: 7 | D9: 163 | E9: 161000371 | F9: 59 | G9: 3512.41 | H9: 265.46 | I9: 1.87 | J9: 0 | K9: 0 | L9: 0 | M9: 0 | N9: 0 | Q9: 0 | R9: =K9+M9+Q9 -> 0 | S9: =R9*5% -> 0 | T9: =R9+S9 -> 0
A10: 164 | B10: 03.07.20 | C10: 8 | D10: 164 | E10: 161000372 | F10: 59 | G10: 3516.11 | H10: 263.36 | I10: 3.47 | J10: 1 | K10: 5000 | L10: 1 | M10: 8850 | N10: 0 | Q10: 0 | R10: =K10+M10+Q10 -> 13850 | S10: =R10*5% -> 692.5 | T10: =R10+S10 -> 14542.5
A11: 165 | B11: 04.07.20 | C11: 9 | D11: 165 | E11: 161000373 | F11: 59 | G11: 3382.12 | H11: 333.06 | I11: 3.18 | J11: 1 | K11: 5000 | L11: 1 | M11: 8700 | N11: 0 | Q11: 0 | R11: =K11+M11+Q11 -> 13700 | S11: =R11*5% -> 685 | T11: =R11+S11 -> 14385
A12: 166 | B12: 04.07.20 | C12: 10 | D12: 166 | E12: 161000374 | F12: 59 | G12: 3488.92 | H12: 286.08 | I12: 0 | J12: 0 | K12: 0 | L12: 0 | M12: 0 | N12: 0 | Q12: 0 | R12: =K12+M12+Q12 -> 0 | S12: =R12*5% -> 0 | T12: =R12+S12 -> 0
A13: 167 | B13: 04.07.20 | C13: 11 | D13: 167 | E13: 161000375 | F13: 59 | G13: 3436.22 | H13: 338.78 | I13: 0 | J13: 0 | K13: 0 | L13: 0 | M13: 0 | N13: 0 | Q13: 0 | R13: =K13+M13+Q13 -> 0 | S13: =R13*5% -> 0 | T13: =R13+S13 -> 0
A14: 168 | B14: 05.07.20 | C14: 12 | D14: 168 | E14: 141000020 | F14: 59 | G14: 3441.61 | H14: 334.39 | I14: 0 | J14: 0 | K14: 0 | L14: 0 | M14: 0 | N14: 0 | Q14: 0 | R14: =K14+M14+Q14 -> 0 | S14: =R14*5% -> 0 | T14: =R14+S14 -> 0
A15: 169 | B15: 05.07.20 | C15: 13 | D15: 169 | E15: 161000376 | F15: 58 | G15: 3340.02 | H15: 371.98 | I15: 0 | J15: 0 | K15: 0 | L15: 0 | M15: 0 | N15: 0 | Q15: 0 | R15: =K15+M15+Q15 -> 0 | S15: =R15*5% -> 0 | T15: =R15+S15 -> 0
A16: 170 | B16: 05.07.20 | C16: 14 | D16: 170 | E16: 161000377 | F16: 57 | G16: 3399.43 | H16: 248.57 | I16: 0 | J16: 0 | K16: 0 | L16: 0 | M16: 0 | N16: 0 | Q16: 0 | R16: =K16+M16+Q16 -> 0 | S16: =R16*5% -> 0 | T16: =R16+S16 -> 0
A17: 171 | B17: 05.07.20 | C17: 15 | D17: 171 | E17: 161000378 | F17: 59 | G17: 3460.22 | H17: 318.36 | I17: 3.58 | J17: 1 | K17: 5000 | L17: 1 | M17: 8850 | N17: 0 | Q17: 0 | R17: =K17+M17+Q17 -> 13850 | S17: =R17*5% -> 692.5 | T17: =R17+S17 -> 14542.5
A18: 172 | B18: 06.07.20 | C18: 16 | D18: 172 | E18: 161000379 | F18: 59 | G18: 3426.42 | H18: 348.58 | I18: 0 | J18: 0 | K18: 0 | L18: 0 | M18: 0 | N18: 0 | O18: 0 | P18: 0 | Q18: 0 | R18: =K18+M18+Q18 -> 0 | S18: =R18*5% -> 0 | T18: =R18+S18 -> 0
A19: 173 | B19: 06.07.20 | C19: 17 | D19: 173 | E19: 141000021 | F19: 59 | G19: 3502.61 | H19: 273.39 | I19: 0 | J19: 0 | K19: 0 | L19: 0 | M19: 0 | N19: 0 | O19: 0 | Q19: 0 | R19: =K19+M19+Q19 -> 0 | S19: =R19*5% -> 0 | T19: =R19+S19 -> 0
A20: 174 | B20: 06.07.20 | C20: 18 | D20: 174 | E20: 151000013 | F20: 58 | G20: 3411.22 | H20: 302.95 | I20: 2.17 | J20: 0 | K20: 0 | L20: 0 | M20: 0 | N20: 0 | O20: 0 | Q20: 0 | R20: =K20+M20+Q20 -> 0 | S20: =R20*5% -> 0 | T20: =R20+S20 -> 0
A21: 175 | B21: 06.07.20 | C21: 19 | D21: 175 | E21: 161000380 | F21: 59 | G21: 3386.21 | H21: 389.79 | I21: 0 | J21: 0 | K21: 0 | L21: 0 | M21: 0 | N21: 0 | O21: 0 | Q21: 0 | R21: =K21+M21+Q21 -> 0 | S21: =R21*5% -> 0 | T21: =R21+S21 -> 0
A22: 176 | B22: 07.07.20 | C22: 20 | D22: 176 | E22: 161000381 | F22: 58 | G22: 3383.63 | H22: 327.37 | I22: 0 | J22: 0 | K22: 0 | L22: 0 | M22: 0 | N22: 0 | O22: 0 | Q22: 0 | R22: =K22+M22+Q22 -> 0 | S22: =R22*5% -> 0 | T22: =R22+S22 -> 0
A23: 177 | B23: 07.07.20 | C23: 21 | D23: 177 | E23: 161000382 | F23: 59 | G23: 3554.01 | H23: 221.99 | I23: 0 | J23: 0 | K23: 0 | L23: 0 | M23: 0 | N23: 0 | O23: 0 | Q23: 0 | R23: =K23+M23+Q23 -> 0 | S23: =R23*5% -> 0 | T23: =R23+S23 -> 0
A24: 178 | B24: 07.07.20 | C24: 22 | D24: 178 | E24: 141000022 | F24: 59 | G24: 3571.61 | H24: 206.38 | I24: 1.99 | J24: 1 | K24: 5000 | L24: 1 | M24: 8850 | N24: 0 | Q24: 0 | R24: =K24+M24+Q24 -> 13850 | S24: =R24*5% -> 692.5 | T24: =R24+S24 -> 14542.5
A25: 179 | B25: 07.07.20 | C25: 23 | D25: 179 | E25: 151000014 | F25: 58 | G25: 3385.82 | H25: 328.36 | I25: 2.18 | J25: 1 | K25: 5000 | L25: 1 | M25: 8700 | N25: 0 | Q25: 0 | R25: =K25+M25+Q25 -> 13700 | S25: =R25*5% -> 685 | T25: =R25+S25 -> 14385
A26: 180 | B26: 08.07.20 | C26: 24 | D26: 180 | E26: 161000383 | F26: 58 | G26: 3528.43 | H26: 198.89 | I26: 16.32 | J26: 4 | K26: 20000 | L26: 1 | M26: 8700 | N26: 0 | Q26: 0 | R26: =K26+M26+Q26 -> 28700 | S26: =R26*5% -> 1435 | T26: =R26+S26 -> 30135
A27: 181 | B27: 08.07.20 | C27: 25 | D27: 181 | E27: 161000384 | F27: 58 | G27: 3525.42 | H27: 195.72 | I27: 9.14 | J27: 3 | K27: 15000 | L27: 1 | M27: 8700 | N27: 0 | Q27: 0 | R27: =K27+M27+Q27 -> 23700 | S27: =R27*5% -> 1185 | T27: =R27+S27 -> 24885
A28: 182 | B28: 08.07.20 | C28: 26 | D28: 182 | E28: 151000015 | F28: 59 | G28: 3615.21 | H28: 170.52 | I28: 9.73 | J28: 3 | K28: 15000 | L28: 1 | M28: 8850 | N28: 0 | Q28: 0 | R28: =K28+M28+Q28 -> 23850 | S28: =R28*5% -> 1192.5 | T28: =R28+S28 -> 25042.5
A29: 183 | B29: 08.07.20 | C29: 27 | D29: 183 | E29: 151000016 | F29: 59 | G29: 3421.02 | H29: 353.98 | I29: 0 | J29: 0 | K29: 0 | L29: 0 | M29: 0 | N29: 0 | Q29: 0 | R29: =K29+M29+Q29 -> 0 | S29: =R29*5% -> 0 | T29: =R29+S29 -> 0
A30: 184 | B30: 09.07.20 | C30: 28 | D30: 184 | E30: 141000023 | F30: 59 | G30: 3437.61 | H30: 338.39 | I30: 0 | J30: 0 | K30: 0 | L30: 0 | M30: 0 | N30: 0 | Q30: 0 | R30: =K30+M30+Q30 -> 0 | S30: =R30*5% -> 0 | T30: =R30+S30 -> 0
A31: 185 | B31: 09.07.20 | C31: 29 | D31: 185 | E31: 141000024 | F31: 59 | G31: 3490.11 | H31: 289.18 | I31: 3.29 | J31: 1 | K31: 5000 | L31: 1 | M31: 8850 | N31: 0 | Q31: 0 | R31: =K31+M31+Q31 -> 13850 | S31: =R31*5% -> 692.5 | T31: =R31+S31 -> 14542.5
A32: 186 | B32: 10.07.20 | C32: 30 | D32: 186 | E32: 161000385 | F32: 59 | G32: 3396.61 | H32: 379.39 | I32: 0 | J32: 0 | K32: 0 | L32: 0 | M32: 0 | N32: 0 | O32: 0 | P32: 0 | Q32: 0 | R32: =K32+M32+Q32 -> 0 | S32: =R32*5% -> 0 | T32: =R32+S32 -> 0
A33: 187 | B33: 10.07.20 | C33: 31 | D33: 187 | E33: 161000386 | F33: 59 | G33: 3508.61 | H33: 268.38 | I33: 0.99 | J33: 0 | K33: 0 | L33: 0 | M33: 0 | N33: 0 | O33: 0 | P33: 0 | Q33: 0 | R33: =K33+M33+Q33 -> 0 | S33: =R33*5% -> 0 | T33: =R33+S33 -> 0
A34: 188 | B34: 10.07.20 | C34: 32 | D34: 188 | E34: 161000387 | F34: 58 | G34: 3423.22 | H34: 292.56 | I34: 3.79 | J34: 1 | K34: 5000 | L34: 1 | M34: 8700 | N34: 0 | Q34: 0 | R34: =K34+M34+Q34 -> 13700 | S34: =R34*5% -> 685 | T34: =R34+S34 -> 14385
A35: 189 | B35: 11.07.20 | C35: 33 | D35: 189 | E35: 141000025 | F35: 58 | G35: 3456.41 | H35: 319.59 | I35: 0 | J35: 0 | K35: 0 | L35: 0 | M35: 0 | N35: 0 | O35: 0 | P35: 0 | Q35: 0 | R35: =K35+M35+Q35 -> 0 | S35: =R35*5% -> 0 | T35: =R35+S35 -> 0
A36: 190 | B36: 12.07.20 | C36: 34 | D36: 190 | E36: 151000017 | F36: 59 | G36: 3501.81 | H36: 274.77 | I36: 0.58 | J36: 0 | K36: 0 | L36: 0 | M36: 0 | N36: 0 | O36: 0 | P36: 0 | Q36: 0 | R36: =K36+M36+Q36 -> 0 | S36: =R36*5% -> 0 | T36: =R36+S36 -> 0
A37: 191 | B37: 13.07.20 | C37: 35 | D37: 191 | E37: 161000388 | F37: 59 | G37: 3456.41 | H37: 319.59 | I37: 0 | J37: 0 | K37: 0 | L37: 0 | M37: 0 | N37: 0 | O37: 0 | P37: 0 | Q37: 0 | R37: =K37+M37+Q37 -> 0 | S37: =R37*5% -> 0 | T37: =R37+S37 -> 0
A38: 192 | B38: 13.07.20 | C38: 36 | D38: 192 | E38: 141000026 | F38: 59 | G38: 3501.61 | H38: 279.36 | I38: 4.97 | J38: 1 | K38: 5000 | L38: 1 | M38: 8850 | N38: 0 | Q38: 0 | R38: =K38+M38+Q38 -> 13850 | S38: =R38*5% -> 692.5 | T38: =R38+S38 -> 14542.5
A39: 193 | B39: 14.07.20 | C39: 37 | D39: 193 | E39: 161000389 | F39: 59 | G39: 3587.22 | H39: 198.14 | I39: 10.36 | J39: 1 | K39: 5000 | L39: 1 | M39: 8850 | N39: 0 | Q39: 0 | R39: =K39+M39+Q39 -> 13850 | S39: =R39*5% -> 692.5 | T39: =R39+S39 -> 14542.5
A40: 194 | B40: 14.07.20 | C40: 38 | D40: 194 | E40: 141000027 | F40: 56 | G40: 3560.24 | H40: 72.6 | I40: 48.84 | J40: 15 | K40: 75000 | L40: 2 | M40: 16800 | N40: 0 | Q40: 0 | R40: =K40+M40+Q40 -> 91800 | S40: =R40*5% -> 4590 | T40: =R40+S40 -> 96390
...

Sheet AUG
A1: AUGUST MONTH RAKE LOADING DATA
A2: SL NO | B2: LOADING DATE | C2: RAKE NO. | D2: PRIORTY NUMBER | E2: R.R NUMBER | F2: NO OF WAGON | G2: NET WEIGHT | H2: UNDER LOAD WT | I2: OVER LOAD WT | J2: O/L WAGON | K2: O/L CHARGE | L2: DETENTION HOURS | M2: DETENTION CHARGES | N2: SHUNTING HOURS | O2: SHUNTING CHARGES | P2: PILOT HOURS | Q2: PILOT CHARGES | R2: PCLA | S2: GST 5% | T2: TOTAL AMOUNT RS
A3: 255 | B3: 01.08.20 | C3: 1 | D3: 255 | E3: 161000442 | F3: 60 | G3: 3579 | H3: 261 | I3: 0 | J3: 0 | K3: 0 | L3: 0 | M3: 0 | N3: 0 | O3: 0 | P3: 0 | Q3: 0 | R3: =K3+M3+Q3 -> 0 | S3: =R3*5% -> 0 | T3: =R3+S3 -> 0
A4: 256 | B4: 01.08.20 | C4: 2 | D4: 256 | E4: 161000443 | F4: 57 | G4: 3372.84 | H4: 274.16 | I4: 0 | J4: 0 | K4: 0 | L4: 0 | M4: 0 | N4: 0 | O4: 0 | P4: 0 | Q4: 0 | R4: =K4+M4+Q4 -> 0 | S4: =R4*5% -> 0 | T4: =R4+S4 -> 0
A5: 257 | B5: 02.08.20 | C5: 3 | D5: 257 | E5: 161000444 | F5: 59 | G5: 3515.01 | H5: 260.99 | I5: 0 | J5: 0 | K5: 0 | L5: 0 | M5: 0 | N5: 0 | O5: 0 | P5: 0 | Q5: 0 | R5: =K5+M5+Q5 -> 0 | S5: =R5*5% -> 0 | T5: =R5+S5 -> 0
A6: 258 | B6: 02.08.20 | C6: 4 | D6: 258 | E6: 161000445 | F6: 60 | G6: 3623.61 | H6: 215.39 | I6: 0 | J6: 0 | K6: 0 | L6: 0 | M6: 0 | N6: 0 | O6: 0 | P6: 0 | Q6: 0 | R6: =K6+M6+Q6 -> 0 | S6: =R6*5% -> 0 | T6: =R6+S6 -> 0
A7: 259 | B7: 03.08.20 | C7: 5 | D7: 259 | E7: 161000446 | F7: 59 | G7: 3579.05 | H7: 195.14 | I7: 2.19 | J7: 1 | K7: 5000 | L7: 1 | M7: 8850 | N7: 0 | Q7: 0 | R7: =K7+M7+Q7 -> 13850 | S7: =R7*5% -> 692.5 | T7: =R7+S7 -> 14542.5
A8: 260 | B8: 04.08.20 | C8: 6 | D8: 260 | E8: 161000447 | F8: 58 | G8: 3631.41 | H8: 207.98 | I8: 0.39 | J8: 0 | K8: 0 | L8: 0 | M8: 0 | N8: 0 | Q8: 0 | R8: =K8+M8+Q8 -> 0 | S8: =R8*5% -> 0 | T8: =R8+S8 -> 0
A9: 261 | B9: 04.08.20 | C9: 7 | D9: 261 | E9: 161000448 | F9: 58 | G9: 3516.23 | H9: 194.96 | I9: 0.19 | J9: 0 | K9: 0 | L9: 0 | M9: 0 | N9: 0 | Q9: 0 | R9: =K9+M9+Q9 -> 0 | S9: =R9*5% -> 0 | T9: =R9+S9 -> 0
A10: 262 | B10: 04.08.20 | C10: 8 | D10: 262 | E10: 161000449 | F10: 60 | G10: 3627.61 | H10: 211.39 | I10: 0 | J10: 0 | K10: 0 | L10: 0 | M10: 0 | N10: 0 | Q10: 0 | R10: =K10+M10+Q10 -> 0 | S10: =R10*5% -> 0 | T10: =R10+S10 -> 0
A11: 263 | B11: 04.08.20 | C11: 9 | D11: 263 | E11: 161000450 | F11: 60 | G11: 3574.62 | H11: 263.38 | I11: 0 | J11: 0 | K11: 0 | L11: 0 | M11: 0 | N11: 0 | Q11: 0 | R11: =K11+M11+Q11 -> 0 | S11: =R11*5% -> 0 | T11: =R11+S11 -> 0
A12: 264 | B12: 05.08.20 | C12: 10 | D12: 264 | E12: 161000451 | F12: 59 | G12: 3499.43 | H12: 274.57 | I12: 0 | J12: 0 | K12: 0 | L12: 0 | M12: 0 | N12: 0 | Q12: 0 | R12: =K12+M12+Q12 -> 0 | S12: =R12*5% -> 0 | T12: =R12+S12 -> 0
A13: 265 | B13: 05.08.20 | C13: 11 | D13: 265 | E13: 161000452 | F13: 60 | G13: 3610.21 | H13: 228.98 | I13: 0.19 | J13: 0 | K13: 0 | L13: 0 | M13: 0 | N13: 0 | Q13: 0 | R13: =K13+M13+Q13 -> 0 | S13: =R13*5% -> 0 | T13: =R13+S13 -> 0
A14: 266 | B14: 06.08.20 | C14: 12 | D14: 266 | E14: 161000453 | F14: 56 | G14: 3365.45 | H14: 217.55 | I14: 0 | J14: 0 | K14: 0 | L14: 0 | M14: 0 | N14: 0 | Q14: 0 | R14: =K14+M14+Q14 -> 0 | S14: =R14*5% -> 0 | T14: =R14+S14 -> 0
A15: 267 | B15: 06.08.20 | C15: 13 | D15: 267 | E15: 161000454 | F15: 60 | G15: 3606.4 | H15: 233.6 | I15: 0 | J15: 0 | K15: 0 | L15: 0 | M15: 0 | N15: 0 | Q15: 0 | R15: =K15+M15+Q15 -> 0 | S15: =R15*5% -> 0 | T15: =R15+S15 -> 0
A16: 268 | B16: 07.08.20 | C16: 14 | D16: 268 | E16: 161000455 | F16: 60 | G16: 3638.61 | H16: 200.39 | I16: 0 | J16: 0 | K16: 0 | L16: 0 | M16: 0 | N16: 0 | Q16: 0 | R16: =K16+M16+Q16 -> 0 | S16: =R16*5% -> 0 | T16: =R16+S16 -> 0
A17: 269 | B17: 08.08.20 | C17: 15 | D17: 269 | E17: 161000456 | F17: 60 | G17: 3630.22 | H17: 207.78 | I17: 0 | J17: 0 | K17: 0 | L17: 0 | M17: 0 | N17: 0 | Q17: 0 | R17: =K17+M17+Q17 -> 0 | S17: =R17*5% -> 0 | T17: =R17+S17 -> 0
A18: 270 | B18: 08.08.20 | C18: 16 | D18: 270 | E18: 161000457 | F18: 60 | G18: 3633.6 | H18: 206.4 | I18: 0 | J18: 0 | K18: 0 | L18: 0 | M18: 0 | N18: 0 | Q18: 0 | R18: =K18+M18+Q18 -> 0 | S18: =R18*5% -> 0 | T18: =R18+S18 -> 0
... A47: 299 | B47: 17.08.20 | C47: 45 | D47: 299 | E47: 161000485 | F47: 60 | G47: 3738.3 | H47: 163.76 | I47: 2.06 | J47: 1 | K47: 5000 | L47: 1 | M47: 9000 | N47: 0 | Q47: 0 | R47: =K47+M47+Q47 -> 14000 | S47: =R47*5% -> 700 | T47: =R47+S47 -> 14700
A48: 300 | B48: 18.08.20 | C48: 46 | D48: 300 | E48: 161000486 | F48: 60 | G48: 3637.63 | H48: 259.77 | I48: 0.4 | J48: 0 | K48: 0 | L48: 0 | M48: 0 | N48: 0 | O48: 0 | P48: 0 | Q48: 0 | R48: =K48+M48+Q48 -> 0 | S48: =R48*5% -> 0 | T48: =R48+S48 -> 0
A49: 301 | B49: 18.08.20 | C49: 47 | D49: 301 | E49: 161000487 | F49: 60 | G49: 3590.81 | H49: 308.19 | I49: 0 | J49: 0 | K49: 0 | L49: 0 | M49: 0 | N49: 0 | O49: 0 | P49: 0 | Q49: 0 | R49: =K49+M49+Q49 -> 0 | S49: =R49*5% -> 0 | T49: =R49+S49 -> 0
A50: 302 | B50: 18.08.20 | C50: 48 | D50: 302 | E50: 161000488 | F50: 60 | G50: 3586.04 | H50: 309.96 | I50: 0 | J50: 0 | K50: 0 | L50: 0 | M50: 0 | N50: 0 | O50: 0 | P50: 0 | Q50: 0 | R50: =K50+M50+Q50 -> 0 | S50: =R50*5% -> 0 | T50: =R50+S50 -> 0
A51: 303 | B51: 19.08.20 | C51: 49 | D51: 303 | E51: 161000489 | F51: 60 | G51: 3737.21 | H51: 171.33 | I51: 0.69 | J51: 6 | K51: 30000 | L51: 1 | M51: 9000 | N51: 0 | Q51: 0 | R51: =K51+M51+Q51 -> 39000 | S51: =R51*5% -> 1950 | T51: =R51+S51 -> 40950
A52: 304 | B52: 19.08.20 | C52: 50 | D52: 304 | E52: 161000490 | F52: 60 | G52: 3596 | H52: 304 | I52: 0 | J52: 0 | K52: 0 | L52: 0 | M52: 0 | N52: 0 | Q52: 0 | R52: =K52+M52+Q52 -> 0 | S52: =R52*5% -> 0 | T52: =R52+S52 -> 0
A53: 305 | B53: 20.08.20 | C53: 51 | D53: 305 | E53: 161000491 | F53: 60 | G53: 3554.6 | H53: 345.4 | I53: 0 | J53: 0 | K53: 0 | L53: 0 | M53: 0 | N53: 0 | Q53: 0 | R53: =K53+M53+Q53 -> 0 | S53: =R53*5% -> 0 | T53: =R53+S53 -> 0
A54: 306 | B54: 20.08.20 | C54: 52 | D54: 306 | E54: 161000492 | F54: 60 | G54: 3581 | H54: 319 | I54: 0 | J54: 0 | K54: 0 | L54: 0 | M54: 0 | N54: 0 | Q54: 0 | R54: =K54+M54+Q54 -> 0 | S54: =R54*5% -> 0 | T54: =R54+S54 -> 0
A55: 307 | B55: 20.08.20 | C55: 53 | D55: 307 | E55: 161000493 | F55: 59 | G55: 3542.84 | H55: 289.16 | I55: 0 | J55: 0 | K55: 0 | L55: 0 | M55: 0 | N55: 0 | Q55: 54000 | R55: =K55+M55+Q55 -> 54000 | S55: =R55*5% -> 2700 | T55: =R55+S55 -> 56700
A56: 308 | B56: 20.08.20 | C56: 54 | D56: 308 | E56: 161000494 | F56: 60 | G56: 3586.04 | H56: 309.96 | I56: 0 | J56: 0 | K56: 0 | L56: 0 | M56: 0 | N56: 0 | Q56: 0 | R56: =K56+M56+Q56 -> 0 | S56: =R56*5% -> 0 | T56: =R56+S56 -> 0
A57: 309 | B57: 21.08.20 | C57: 55 | D57: 309 | E57: 161000495 | F57: 57 | G57: 3377.05 | H57: 261.95 | I57: 0 | J57: 0 | K57: 0 | L57: 0 | M57: 0 | N57: 0 | Q57: 0 | R57: =K57+M57+Q57 -> 0 | S57: =R57*5% -> 0 | T57: =R57+S57 -> 0
A58: 310 | B58: 21.08.20 | C58: 56 | D58: 310 | E58: 161000496 | F58: 60 | G58: 3577.2 | H58: 322.8 | I58: 0 | J58: 0 | K58: 0 | L58: 0 | M58: 0 | N58: 0 | Q58: 0 | R58: =K58+M58+Q58 -> 0 | S58: =R58*5% -> 0 | T58: =R58+S58 -> 0
A59: 311 | B59: 21.08.20 | C59: 57 | D59: 311 | E59: 161000497 | F59: 60 | G59: 3601.4 | H59: 298.6 | I59: 0 | J59: 0 | K59: 0 | L59: 0 | M59: 0 | N59: 0 | Q59: 0 | R59: =K59+M59+Q59 -> 0 | S59: =R59*5% -> 0 | T59: =R59+S59 -> 0
A60: 312 | B60: 23.08.20 | C60: 58 | D60: 312 | E60: 161000498 | F60: 59 | G60: 3558.61 | H60: 276.39 | I60: 0 | J60: 0 | K60: 0 | L60: 0 | M60: 0 | N60: 0 | Q60: 0 | R60: =K60+M60+Q60 -> 0 | S60: =R60*5% -> 0 | T60: =R60+S60 -> 0
A61: 313 | B61: 23.08.20 | C61: 59 | D61: 313 | E61: 161000499 | F61: 60 | G61: 3575 | H61: 325 | I61: 0 | J61: 0 | K61: 0 | L61: 0 | M61: 0 | N61: 0 | Q61: 0 | R61: =K61+M61+Q61 -> 0 | S61: =R61*5% -> 0 | T61: =R61+S61 -> 0
A62: 314 | B62: 24.08.20 | C62: 60 | D62: 314 | E62: 161000500 | F62: 57 | G62: 3442.63 | H62: 262.37 | I62: 0 | J62: 0 | K62: 0 | L62: 0 | M62: 0 | N62: 0 | Q62: 0 | R62: =K62+M62+Q62 -> 0 | S62: =R62*5% -> 0 | T62: =R62+S62 -> 0
... A80: 332 | B80: 30.08.20 | C80: 78 | D80: 332 | E80: 161000518 | F80: 60 | G80: 3682.4 | H80: 218.99 | I80: 1.39 | J80: 1 | K80: 5000 | L80: 1 | M80: 9000 | N80: 0 | Q80: 0 | R80: =K80+M80+Q80 -> 14000 | S80: =R80*5% -> 700 | T80: =R80+S80 -> 14700
A81: 333 | B81: 30.08.20 | C81: 79 | D81: 333 | E81: 161000519 | F81: 58 | G81: 3407.04 | H81: 400.96 | I81: 0 | J81: 0 | K81: 0 | L81: 0 | M81: 0 | N81: 0 | O81: 0 | P81: 0 | Q81: 0 | R81: =K81+M81+Q81 -> 0 | S81: =R81*5% -> 0 | T81: =R81+S81 -> 0
A82: 334 | B82: 31.08.20 | C82: 80 | D82: 334 | E82: 161000520 | F82: 58 | G82: 3289.33 | H82: 479.67 | I82: 0 | J82: 0 | K82: 0 | L82: 0 | M82: 0 | N82: 0 | O82: 0 | P82: 0 | Q82: 0 | R82: =K82+M82+Q82 -> 0 | S82: =R82*5% -> 0 | T82: =R82+S82 -> 0 | U82: 478800
A83: 335 | B83: 31.08.20 | C83: 81 | D83: 335 | E83: 161000521 | F83: 58 | G83: 3234.35 | H83: 532.65 | I83: 0 | J83: 0 | K83: 0 | L83: 0 | M83: 0 | N83: 0 | O83: 0 | P83: 0 | Q83: 0 | R83: =K83+M83+Q83 -> 0 | S83: =R83*5% -> 0 | T83: =R83+S83 -> 0 | U83: 37800
A84: 336 | B84: 31.08.20 | C84: 82 | D84: 336 | E84: 161000522 | F84: 58 | G84: 3299.84 | H84: 468 | I84: 0 | J84: 0 | K84: 0 | L84: 0 | M84: 0 | N84: 0 | O84: 0 | P84: 0 | Q84: 0 | R84: =K84+M84+Q84 -> 0 | S84: =R84*5% -> 0 | T84: =R84+S84 -> 0 | U84: 56700
E85: TOTAL | F85: =SUM(F3:F84) -> 4871 | G85: =SUM(G3:G84) -> 292214.44 | H85: =SUM(H3:H84) -> 21873.3 | I85: =SUM(I3:I84) -> 31.67 | J85: =SUM(J3:J84) -> 18 | K85: =SUM(K3:K84) -> 90000 | L85: =SUM(L3:L84) -> 8 | M85: =SUM(M3:M84) -> 71700 | ... T85: =SUM(T3:T84) -> 758824.5 | U85: =SUM(U82:U84) -> 573300
...

Sheet SEP
A1: SEPTEMBER MONTH RAKE LOADING DATA
A2: SL NO | B2: LOADING DATE | C2: RAKE NO. | D2: PRIORTY NUMBER | E2: R.R NUMBER | F2: NO OF WAGON | G2: NET WEIGHT | H2: UNDER LOAD WT | I2: OVER LOAD WT | J2: O/L WAGON | K2: O/L CHARGE | L2: DETENTION HOURS | M2: DETENTION CHARGES | N2: SHUNTING HOURS | O2: SHUNTING CHARGES | P2: PILOT HOURS | Q2: PILOT CHARGES | R2: PCLA | S2: GST 5% | T2: TOTAL AMOUNT RS
A3: 337 | B3: 01.09.20 | C3: 1 | D3: 337 | E3: 161000523 | F3: 60 | G3: 3563.1 | H3: 336.9 | I3: 0 | J3: 0 | K3: 0 | L3: 0 | M3: 0 | N3: 0 | O3: 0 | P3: 0 | Q3: 0 | R3: =K3+M3+Q3 -> 0 | S3: =R3*5% -> 0 | T3: =R3+S3 -> 0
A4: 338 | B4: 02.09.20 | C4: 2 | D4: 338 | E4: 161000524 | F4: 57 | G4: 3358.03 | H4: 346.97 | I4: 0 | J4: 0 | K4: 0 | L4: 0 | M4: 0 | N4: 0 | O4: 0 | P4: 0 | Q4: 0 | R4: =K4+M4+Q4 -> 0 | S4: =R4*5% -> 0 | T4: =R4+S4 -> 0
A5: 339 | B5: 02.09.20 | C5: 3 | D5: 339 | E5: 161000525 | F5: 60 | G5: 3505.84 | H5: 390.16 | I5: 0 | J5: 0 | K5: 0 | L5: 0 | M5: 0 | N5: 0 | O5: 0 | P5: 0 | Q5: 0 | R5: =K5+M5+Q5 -> 0 | S5: =R5*5% -> 0 | T5: =R5+S5 -> 0
A6: 340 | B6: 02.09.20 | C6: 4 | D6: 340 | E6: 161000526 | F6: 60 | G6: 3587.6 | H6: 312.4 | I6: 0 | J6: 0 | K6: 0 | L6: 0 | M6: 0 | N6: 0 | O6: 0 | P6: 0 | Q6: 0 | R6: =K6+M6+Q6 -> 0 | S6: =R6*5% -> 0 | T6: =R6+S6 -> 0
A7: 341 | B7: 02.09.20 | C7: 5 | D7: 341 | E7: 161000527 | F7: 60 | G7: 3345.74 | H7: 422.26 | I7: 0 | J7: 0 | K7: 0 | L7: 0 | M7: 0 | N7: 0 | O7: 0 | P7: 0 | Q7: 0 | R7: =K7+M7+Q7 -> 0 | S7: =R7*5% -> 0 | T7: =R7+S7 -> 0
A8: 342 | B8: 03.09.20 | C8: 6 | D8: 342 | E8: 161000528 | F8: 58 | G8: 3475.44 | H8: 292.56 | I8: 0 | J8: 0 | K8: 0 | L8: 0 | M8: 0 | N8: 0 | O8: 0 | P8: 0 | Q8: 0 | R8: =K8+M8+Q8 -> 0 | S8: =R8*5% -> 0 | T8: =R8+S8 -> 0
A9: 343 | B9: 03.09.20 | C9: 7 | D9: 343 | E9: 161000529 | F9: 59 | G9: 3529.92 | H9: 304.08 | I9: 0 | J9: 0 | K9: 0 | L9: 0 | M9: 0 | N9: 0 | O9: 0 | P9: 0 | Q9: 0 | R9: =K9+M9+Q9 -> 0 | S9: =R9*5% -> 0 | T9: =R9+S9 -> 0
A10: 344 | B10: 03.09.20 | C10: 8 | D10: 344 | E10: 161000530 | F10: 58 | G10: 3313.53 | H10: 391.47 | I10: 0 | J10: 0 | K10: 0 | L10: 0 | M10: 0 | N10: 0 | O10: 0 | P10: 0 | Q10: 0 | R10: =K10+M10+Q10 -> 0 | S10: =R10*5% -> 0 | T10: =R10+S10 -> 0
A11: 345 | B11: 03.09.20 | C11: 9 | D11: 345 | E11: 161000531 | F11: 60 | G11: 3431.64 | H11: 464.36 | I11: 0 | J11: 0 | K11: 0 | L11: 0 | M11: 0 | N11: 0 | O11: 0 | P11: 0 | Q11: 0 | R11: =K11+M11+Q11 -> 0 | S11: =R11*5% -> 0 | T11: =R11+S11 -> 0
A12: 346 | B12: 04.09.20 | C12: 10 | D12: 346 | E12: 161000532 | F12: 60 | G12: 3359.22 | H12: 408.78 | I12: 0 | J12: 0 | K12: 0 | L12: 0 | M12: 0 | N12: 0 | O12: 0 | P12: 0 | Q12: 0 | R12: =K12+M12+Q12 -> 0 | S12: =R12*5% -> 0 | T12: =R12+S12 -> 0
A13: 347 | B13: 04.09.20 | C13: 11 | D13: 347 | E13: 161000533 | F13: 60 | G13: 3491.6 | H13: 408.4 | I13: 0 | J13: 0 | K13: 0 | L13: 0 | M13: 0 | N13: 0 | O13: 0 | P13: 0 | Q13: 0 | R13: =K13+M13+Q13 -> 0 | S13: =R13*5% -> 0 | T13: =R13+S13 -> 0
A14: 348 | B14: 04.09.20 | C14: 12 | D14: 348 | E14: 161000534 | F14: 60 | G14: 3539.41 | H14: 359.59 | I14: 0 | J14: 0 | K14: 0 | L14: 0 | M14: 0 | N14: 0 | O14: 0 | P14: 0 | Q14: 0 | R14: =K14+M14+Q14 -> 0 | S14: =R14*5% -> 0 | T14: =R14+S14 -> 0
... A18: 352 | B18: 05.09.20 | C18: 16 | D18: 352 | E18: 161000537 | F18: 60 | G18: 3496.42 | H18: 337.58 | I18: 0 | J18: 0 | K18: 0 | L18: 0 | M18: 0 | N18: 0 | O18: 0 | P18: 0 | Q18: 0 | R18: =K18+M18+Q18 -> 0 | S18: =R18*5% -> 0 | T18: =R18+S18 -> 0
A19: 353 | B19: 06.09.20 | C19: 17 | D19: 353 | E19: 161000538 | F19: 59 | G19: 3508.21 | H19: 326.79 | I19: 0 | J19: 0 | K19: 0 | L19: 0 | M19: 0 | N19: 0 | O19: 0 | P19: 0 | Q19: 0 | R19: =K19+M19+Q19 -> 0 | S19: =R19*5% -> 0 | T19: =R19+S19 -> 0 | U19: LINK FAILED 0:30
A20: 354 | B20: 06.09.20 | C20: 18 | D20: 354 | E20: 162000002 | F20: 58 | G20: 3391.02 | H20: 378.98 | I20: 0 | J20: 0 | K20: 0 | L20: 0 | M20: 0 | N20: 0 | O20: 0 | P20: 0 | Q20: 0 | R20: =K20+M20+Q20 -> 0 | S20: =R20*5% -> 0 | T20: =R20+S20 -> 0
A21: 355 | B21: 07.09.20 | C21: 19 | D21: 355 | E21: 161000539 | F21: 56 | G21: 3338.49 | H21: 297.31 | I21: 0 | J21: 0 | K21: 0 | L21: 0 | M21: 0 | N21: 0 | O21: 0 | P21: 0 | Q21: 0 | R21: =K21+M21+Q21 -> 0 | S21: =R21*5% -> 0 | T21: =R21+S21 -> 0
A22: 356 | B22: 07.09.20 | C22: 20 | D22: 356 | E22: 161000540 | F22: 58 | G22: 3435.06 | H22: 330.94 | I22: 0 | J22: 0 | K22: 0 | L22: 0 | M22: 0 | N22: 0 | O22: 0 | P22: 0 | Q22: 0 | R22: =K22+M22+Q22 -> 0 | S22: =R22*5% -> 0 | T22: =R22+S22 -> 0
A23: 357 | B23: 07.09.20 | C23: 21 | D23: 357 | E23: 161000541 | F23: 58 | G23: 3509.83 | H23: 259.17 | I23: 0 | J23: 0 | K23: 0 | L23: 0 | M23: 0 | N23: 0 | O23: 0 | P23: 0 | Q23: 0 | R23: =K23+M23+Q23 -> 0 | S23: =R23*5% -> 0 | T23: =R23+S23 -> 0
A24: 358 | B24: 08.09.20 | C24: 22 | D24: 358 | E24: 162000003 | F24: 57 | G24: 3416.45 | H24: 286.65 | I24: 0 | J24: 0 | K24: 0 | L24: 0 | M24: 0 | N24: 0 | O24: 0 | P24: 0 | Q24: 0 | R24: =K24+M24+Q24 -> 0 | S24: =R24*5% -> 0 | T24: =R24+S24 -> 0
A25: 359 | B25: 08.09.20 | C25: 23 | D25: 359 | E25: 161000542 | F25: 59 | G25: 3510.05 | H25: 320.95 | I25: 0 | J25: 0 | K25: 0 | L25: 0 | M25: 0 | N25: 0 | O25: 0 | P25: 0 | Q25: 0 | R25: =K25+M25+Q25 -> 0 | S25: =R25*5% -> 0 | T25: =R25+S25 -> 0 | U25: BAKREHWAR | V25: 106 KM
A26: 360 | B26: 08.09.20 | C26: 24 | D26: 360 | E26: 161000543 | F26: 59 | G26: 3510.41 | H26: 324.59 | I26: 0 | J26: 0 | K26: 0 | L26: 0 | M26: 0 | N26: 0 | O26: 0 | P26: 0 | Q26: 0 | R26: =K26+M26+Q26 -> 0 | S26: =R26*5% -> 0 | T26: =R26+S26 -> 0
A27: 361 | B27: 08.09.20 | C27: 25 | D27: 361 | E27: 162000004 | F27: 59 | G27: 3545.01 | H27: 289.99 | I27: 0 | J27: 0 | K27: 0 | L27: 0 | M27: 0 | N27: 0 | O27: 0 | P27: 0 | Q27: 0 | R27: =K27+M27+Q27 -> 0 | S27: =R27*5% -> 0 | T27: =R27+S27 -> 0 | U27: SANTHALDIH | V27: 242 KM
A28: 362 | B28: 09.09.20 | C28: 26 | D28: 362 | E28: 161000544 | F28: 58 | G28: 3455.06 | H28: 310.94 | I28: 0 | J28: 0 | K28: 0 | L28: 0 | M28: 0 | N28: 0 | O28: 0 | P28: 0 | Q28: 0 | R28: =K28+M28+Q28 -> 0 | S28: =R28*5% -> 0 | T28: =R28+S28 -> 0
A29: 363 | B29: 09.09.20 | C29: 27 | D29: 363 | E29: 161000545 | F29: 57 | G29: 3388.66 | H29: 313.34 | I29: 0 | J29: 0 | K29: 0 | L29: 0 | M29: 0 | N29: 0 | O29: 0 | P29: 0 | Q29: 0 | R29: =K29+M29+Q29 -> 0 | S29: =R29*5% -> 0 | T29: =R29+S29 -> 0
A30: 364 | B30: 09.09.20 | C30: 28 | D30: 364 | E30: 161000546 | F30: 57 | G30: 3387.27 | H30: 313.73 | I30: 0 | J30: 0 | K30: 0 | L30: 0 | M30: 0 | N30: 0 | O30: 0 | P30: 0 | Q30: 0 | R30: =K30+M30+Q30 -> 0 | S30: =R30*5% -> 0 | T30: =R30+S30 -> 0
A31: 365 | B31: 10.09.20 | C31: 29 | D31: 365 | E31: 162000005 | F31: 58 | G31: 3446.63 | H31: 322.37 | I31: 0 | J31: 0 | K31: 0 | L31: 0 | M31: 0 | N31: 0 | O31: 0 | P31: 0 | Q31: 0 | R31: =K31+M31+Q31 -> 0 | S31: =R31*5% -> 0 | T31: =R31+S31 -> 0
A32: 366 | B32: 10.09.20 | C32: 30 | D32: 366 | E32: 161000547 | F32: 59 | G32: 3464.21 | H32: 370.79 | I32: 0 | J32: 0 | K32: 0 | L32: 0 | M32: 0 | N32: 0 | O32: 0 | P32: 0 | Q32: 0 | R32: =K32+M32+Q32 -> 0 | S32: =R32*5% -> 0 | T32: =R32+S32 -> 0
A33: 367 | B33: 10.09.20 | C33: 31 | D33: 367 | E33: 161000548 | F33: 55 | G33: 3241.47 | H33: 331.53 | I33: 0 | J33: 0 | K33: 0 | L33: 0 | M33: 0 | N33: 0 | O33: 0 | P33: 0 | Q33: 0 | R33: =K33+M33+Q33 -> 0 | S33: =R33*5% -> 0 | T33: =R33+S33 -> 0
A34: 368 | B34: 10.09.20 | C34: 32 | D34: 368 | E34: 161000549 | F34: 59 | G34: 3523.22 | H34: 310.78 | I34: 0 | J34: 0 | K34: 0 | L34: 0 | M34: 0 | N34: 0 | O34: 0 | P34: 0 | Q34: 0 | R34: =K34+M34+Q34 -> 0 | S34: =R34*5% -> 0 | T34: =R34+S34 -> 0
A35: 369 | B35: 11.09.20 | C35: 33 | D35: 369 | E35: 161000550 | F35: 59 | G35: 3532.45 | H35: 298.55 | I35: 0 | J35: 0 | K35: 0 | L35: 0 | M35: 0 | N35: 0 | O35: 0 | P35: 0 | Q35: 0 | R35: =K35+M35+Q35 -> 0 | S35: =R35*5% -> 0 | T35: =R35+S35 -> 0
A36: 370 | B36: 11.09.20 | C36: 34 | D36: 370 | E36: 162000006 | F36: 60 | G36: 3445.86 | H36: 384.14 | I36: 0 | J36: 0 | K36: 0 | L36: 0 | M36: 0 | N36: 0 | O36: 0 | P36: 0 | Q36: 0 | R36: =K36+M36+Q36 -> 0 | S36: =R36*5% -> 0 | T36: =R36+S36 -> 0
A37: 371 | B37: 11.09.20 | C37: 35 | D37: 371 | E37: 161000551 | F37: 58 | G37: 3399.82 | H37: 370.18 | I37: 0 | J37: 0 | K37: 0 | L37: 0 | M37: 0 | N37: 0 | O37: 0 | P37: 0 | Q37: 0 | R37: =K37+M37+Q37 -> 0 | S37: =R37*5% -> 0 | T37: =R37+S37 -> 0
A38: 372 | B38: 12.09.20 | C38: 36 | D38: 372 | E38: 161000552 | F38: 57 | G38: 3363.65 | H38: 339.35 | I38: 0 | J38: 0 | K38: 0 | L38: 0 | M38: 0 | N38: 0 | O38: 0 | P38: 0 | Q38: 0 | R38: =K38+M38+Q38 -> 0 | S38: =R38*5% -> 0 | T38: =R38+S38 -> 0
A39: 373 | B39: 12.09.20 | C39: 37 | D39: 373 | E39: 161000553 | F39: 59 | G39: 3524.02 | H39: 309.98 | I39: 0 | J39: 0 | K39: 0 | L39: 0 | M39: 0 | N39: 0 | O39: 0 | P39: 0 | Q39: 0 | R39: =K39+M39+Q39 -> 0 | S39: =R39*5% -> 0 | T39: =R39+S39 -> 0
... A81: 415 | B81: 25.09.20 | C81: 79 | D81: 415 | E81: 161000589 | F81: 58 | G81: 3465.82 | H81: 304.18 | I81: 0 | J81: 0 | K81: 0 | L81: 0 | M81: 0 | N81: 0 | O81: 0 | P81: 0 | Q81: 0 | R81: =K81+M81+Q81 -> 0 | S81: =R81*5% -> 0 | T81: =R81+S81 -> 0
A82: 416 | B82: 26.09.20 | C82: 80 | D82: 416 | E82: 161000590 | F82: 57 | G82: 3484.66 | H82: 224.9 | I82: 7.56 | J82: 4 | K82: 0 | L82: 1 | M82: 8550 | N82: 0 | Q82: 0 | R82: =K82+M82+Q82 -> 8550 | S82: =R82*5% -> 427.5 | T82: =R82+S82 -> 8977.5
A83: 417 | B83: 26.09.20 | C83: 81 | D83: 417 | E83: 161000591 | F83: 58 | G83: 3473.06 | H83: 294.53 | I83: 1.59 | J83: 1 | K83: 0 | L83: 1 | M83: 8700 | N83: 0 | Q83: 0 | R83: =K83+M83+Q83 -> 8700 | S83: =R83*5% -> 435 | T83: =R83+S83 -> 9135
A84: 418 | B84: 26.09.20 | C84: 82 | D84: 418 | E84: 141000035 | F84: 56 | G84: 3303.85 | H84: 335.15 | I84: 0 | J84: 0 | K84: 0 | L84: 0 | M84: 0 | N84: 2 | Q84: 29980 | R84: =K84+M84+Q84 -> 29980 | S84: =R84*5% -> 1499 | T84: =R84+S84 -> 31479 | U84: PILOT D.C
...

Sheet OCT
A1: OCTOBER MONTH RAKE LOADING DATA
A2: SL NO | B2: LOADING DATE | C2: RAKE NO. | D2: PRIORTY NUMBER | E2: R.R NUMBER | F2: NO OF WAGON | G2: NET WEIGHT | H2: UNDER LOAD WT | I2: OVER LOAD WT | J2: O/L WAGON | K2: O/L CHARGE | L2: DETENTION HOURS | M2: DETENTION CHARGES | N2: SHUNTING HOURS | O2: SHUNTING CHARGES | P2: PILOT HOURS | Q2: PILOT CHARGES | R2: PCLA | S2: GST 5% | T2: TOTAL AMOUNT RS
A3: 428 | B3: 01.10.20 | C3: 1 | D3: 428 | E3: 161000600 | F3: 58 | G3: 3449.22 | H3: 320.78 | I3: 0 | J3: 0 | K3: 0 | L3: 0 | M3: 0 | N3: 0 | O3: 0 | P3: 0 | Q3: 0 | R3: =K3+M3+Q3 -> 0 | S3: =R3*5% -> 0 | T3: =R3+S3 -> 0
A4: 429 | B4: 01.10.20 | C4: 2 | D4: 1 | E4: 141000037 | F4: 59 | G4: 3544.21 | H4: 290.79 | I4: 0 | J4: 0 | K4: 0 | L4: 0 | M4: 0 | N4: 0 | O4: 0 | P4: 0 | Q4: 0 | R4: =K4+M4+Q4 -> 0 | S4: =R4*5% -> 0 | T4: =R4+S4 -> 0
A5: 430 | B5: 01.10.20 | C5: 3 | D5: 2 | E5: 161000601 | F5: 59 | G5: 3512.63 | H5: 320.37 | I5: 0 | J5: 0 | K5: 0 | L5: 0 | M5: 0 | N5: 0 | O5: 0 | P5: 0 | Q5: 0 | R5: =K5+M5+Q5 -> 0 | S5: =R5*5% -> 0 | T5: =R5+S5 -> 0
A6: 431 | B6: 03.10.20 | C6: 4 | D6: 3 | E6: 161000602 | F6: 59 | G6: 3551.26 | H6: 278.74 | I6: 0 | J6: 0 | K6: 0 | L6: 0 | M6: 0 | N6: 0 | O6: 0 | P6: 0 | Q6: 0 | R6: =K6+M6+Q6 -> 0 | S6: =R6*5% -> 0 | T6: =R6+S6 -> 0
A7: 432 | B7: 06.10.20 | C7: 5 | D7: 4 | E7: 161000603 | F7: 59 | G7: 3484.43 | H7: 348.57 | I7: 0 | J7: 0 | K7: 0 | L7: 0 | M7: 0 | N7: 0 | O7: 0 | P7: 0 | Q7: 0 | R7: =K7+M7+Q7 -> 0 | S7: =R7*5% -> 0 | T7: =R7+S7 -> 0
A8: 433 | B8: 07.10.20 | C8: 6 | D8: 5 | E8: 161000604 | F8: 59 | G8: 3552.82 | H8: 281.18 | I8: 0 | J8: 0 | K8: 0 | L8: 0 | M8: 0 | N8: 0 | O8: 0 | P8: 0 | Q8: 0 | R8: =K8+M8+Q8 -> 0 | S8: =R8*5% -> 0 | T8: =R8+S8 -> 0
A9: 434 | B9: 07.10.20 | C9: 7 | D9: 6 | E9: 161000605 | F9: 58 | G9: 3479.25 | H9: 287.75 | I9: 0 | J9: 0 | K9: 0 | L9: 0 | M9: 0 | N9: 0 | O9: 0 | P9: 0 | Q9: 0 | R9: =K9+M9+Q9 -> 0 | S9: =R9*5% -> 0 | T9: =R9+S9 -> 0
A10: 435 | B10: 07.10.20 | C10: 8 | D10: 7 | E10: 161000606 | F10: 58 | G10: 3449.82 | H10: 320.18 | I10: 0 | J10: 0 | K10: 0 | L10: 0 | M10: 0 | N10: 0 | O10: 0 | P10: 0 | Q10: 0 | R10: =K10+M10+Q10 -> 0 | S10: =R10*5% -> 0 | T10: =R10+S10 -> 0
A11: 436 | B11: 07.10.20 | C11: 9 | D11: 8 | E11: 161000607 | F11: 59 | G11: 3563.22 | H11: 270.78 | I11: 0 | J11: 0 | K11: 0 | L11: 0 | M11: 0 | N11: 0 | O11: 0 | P11: 0 | Q11: 0 | R11: =K11+M11+Q11 -> 0 | S11: =R11*5% -> 0 | T11: =R11+S11 -> 0
A12: 437 | B12: 07.10.20 | C12: 10 | D12: 9 | E12: 161000608 | F12: 52 | G12: 3094.96 | H12: 277.83 | I12: 0 | J12: 1 | K12: 0 | L12: 1 | M12: 7800 | N12: 0 | O12: 0 | P12: 0 | Q12: 0 | R12: =K12+M12+Q12 -> 7800 | S12: =R12*5% -> 390 | T12: =R12+S12 -> 8190
A13: 438 | B13: 07.10.20 | C13: 11 | D13: 10 | E13: 161000609 | F13: 59 | G13: 3539.81 | H13: 295.19 | I13: 0 | J13: 0 | K13: 0 | L13: 0 | M13: 0 | N13: 0 | O13: 0 | P13: 0 | Q13: 0 | R13: =K13+M13+Q13 -> 0 | S13: =R13*5% -> 0 | T13: =R13+S13 -> 0
A14: 439 | B14: 08.10.20 | C14: 12 | D14: 11 | E14: 161000610 | F14: 59 | G14: 3548.22 | H14: 285.78 | I14: 0 | J14: 0 | K14: 0 | L14: 0 | M14: 0 | N14: 0 | O14: 0 | P14: 0 | Q14: 0 | R14: =K14+M14+Q14 -> 0 | S14: =R14*5% -> 0 | T14: =R14+S14 -> 0
... A30: 455 | B30: 12.10.20 | C30: 28 | D30: 27 | E30: 161000624 | F30: 58 | G30: 3474.02 | H30: 295.98 | I30: 0 | J30: 0 | K30: 0 | L30: 0 | M30: 0 | N30: 0 | O30: 0 | P30: 0 | Q30: 0 | R30: =K30+M30+Q30 -> 0 | S30: =R30*5% -> 0 | T30: =R30+S30 -> 0
A31: 456 | B31: 12.10.20 | C31: 29 | D31: 28 | E31: 141000039 | F31: 59 | G31: 3576.42 | H31: 257.58 | I31: 0 | J31: 0 | K31: 0 | L31: 0 | M31: 0 | N31: 0 | O31: 0 | P31: 0 | Q31: 0 | R31: =K31+M31+Q31 -> 0 | S31: =R31*5% -> 0 | T31: =R31+S31 -> 0 | U31: 13.10.20 | V31: SAMPLE SENT
A32: 457 | B32: 13.10.20 | C32: 30 | D32: 29 | E32: 142000001 | F32: 53 | G32: 3186.36 | H32: 249.64 | I32: 0 | J32: 0 | K32: 0 | L32: 0 | M32: 0 | N32: 0 | O32: 0 | P32: 0 | Q32: 0 | R32: =K32+M32+Q32 -> 0 | S32: =R32*5% -> 0 | T32: =R32+S32 -> 0
A33: 458 | B33: 13.10.20 | C33: 31 | D33: 30 | E33: 161000625 | F33: 59 | G33: 3556.82 | H33: 277.18 | I33: 0 | J33: 0 | K33: 0 | L33: 0 | M33: 0 | N33: 0 | O33: 0 | P33: 0 | Q33: 0 | R33: =K33+M33+Q33 -> 0 | S33: =R33*5% -> 0 | T33: =R33+S33 -> 0
A34: 459 | B34: 13.10.20 | C34: 32 | D34: 31 | E34: 161000626 | F34: 59 | G34: 3564.22 | H34: 269.78 | I34: 0 | J34: 0 | K34: 0 | L34: 0 | M34: 0 | N34: 0 | O34: 0 | P34: 0 | Q34: 0 | R34: =K34+M34+Q34 -> 0 | S34: =R34*5% -> 0 | T34: =R34+S34 -> 0
A35: 460 | B35: 13.10.20 | C35: 33 | D35: 32 | E35: 141000040 | F35: 59 | G35: 3558.01 | H35: 276.99 | I35: 0 | J35: 0 | K35: 0 | L35: 0 | M35: 0 | N35: 0 | O35: 0 | P35: 0 | Q35: 0 | R35: =K35+M35+Q35 -> 0 | S35: =R35*5% -> 0 | T35: =R35+S35 -> 0
A36: 461 | B36: 13.10.20 | C36: 34 | D36: 33 | E36: 162000012 | F36: 59 | G36: 3527.81 | H36: 307.19 | I36: 0 | J36: 0 | K36: 0 | L36: 0 | M36: 0 | N36: 0 | O36: 0 | P36: 0 | Q36: 0 | R36: =K36+M36+Q36 -> 0 | S36: =R36*5% -> 0 | T36: =R36+S36 -> 0
A37: 462 | B37: 14.10.20 | C37: 35 | D37: 34 | E37: 161000627 | F37: 58 | G37: 3486.83 | H37: 282.17 | I37: 0 | J37: 0 | K37: 0 | L37: 0 | M37: 0 | N37: 0 | O37: 0 | P37: 0 | Q37: 0 | R37: =K37+M37+Q37 -> 0 | S37: =R37*5% -> 0 | T37: =R37+S37 -> 0
A38: 463 | B38: 14.10.20 | C38: 36 | D38: 35 | E38: 161000628 | F38: 59 | G38: 3539.26 | H38: 290.74 | I38: 0 | J38: 0 | K38: 0 | L38: 0 | M38: 0 | N38: 0 | O38: 0 | P38: 0 | Q38: 0 | R38: =K38+M38+Q38 -> 0 | S38: =R38*5% -> 0 | T38: =R38+S38 -> 0
A39: 464 | B39: 14.10.20 | C39: 37 | D39: 36 | E39: 161000629 | F39: 58 | G39: 3515.42 | H39: 254.58 | I39: 0 | J39: 0 | K39: 0 | L39: 0 | M39: 0 | N39: 0 | O39: 0 | P39: 0 | Q39: 0 | R39: =K39+M39+Q39 -> 0 | S39: =R39*5% -> 0 | T39: =R39+S39 -> 0
A40: 465 | B40: 14.10.20 | C40: 38 | D40: 37 | E40: 161000630 | F40: 58 | G40: 3526.82 | H40: 243.18 | I40: 0 | J40: 0 | K40: 0 | L40: 0 | M40: 0 | N40: 0 | O40: 0 | P40: 0 | Q40: 0 | R40: =K40+M40+Q40 -> 0 | S40: =R40*5% -> 0 | T40: =R40+S40 -> 0
A41: 466 | B41: 14.10.20 | C41: 39 | D41: 38 | E41: 161000631 | F41: 58 | G41: 3462.62 | H41: 307.38 | I41: 0 | J41: 0 | K41: 0 | L41: 0 | M41: 0 | N41: 0 | O41: 0 | P41: 0 | Q41: 0 | R41: =K41+M41+Q41 -> 0 | S41: =R41*5% -> 0 | T41: =R41+S41 -> 0
A42: 467 | B42: 15.10.20 | C42: 40 | D42: 39 | E42: 161000632 | F42: 57 | G42: 3427.83 | H42: 277.17 | I42: 0 | J42: 0 | K42: 0 | L42: 0 | M42: 0 | N42: 0 | O42: 0 | P42: 0 | Q42: 0 | R42: =K42+M42+Q42 -> 0 | S42: =R42*5% -> 0 | T42: =R42+S42 -> 0
A43: 468 | B43: 15.10.20 | C43: 41 | D43: 40 | E43: 161000633 | F43: 57 | G43: 3392.23 | H43: 312.77 | I43: 0 | J43: 0 | K43: 0 | L43: 0 | M43: 0 | N43: 0 | O43: 0 | P43: 0 | Q43: 0 | R43: =K43+M43+Q43 -> 0 | S43: =R43*5% -> 0 | T43: =R43+S43 -> 0
... A57: 482 | B57: 17.10.20 | C57: 55 | D57: 54 | E57: 161000644 | F57: 57 | G57: 3407.44 | H57: 296.56 | I57: 0 | J57: 0 | K57: 0 | L57: 0 | M57: 0 | N57: 0 | O57: 0 | P57: 0 | Q57: 0 | R57: =K57+M57+Q57 -> 0 | S57: =R57*5% -> 0 | T57: =R57+S57 -> 0
A58: 483 | B58: 17.10.20 | C58: 56 | D58: 55 | E58: 141000041 | F58: 58 | G58: 3493.42 | H58: 276.58 | I58: 0 | J58: 0 | K58: 0 | L58: 0 | M58: 0 | N58: 0 | O58: 0 | P58: 0 | Q58: 0 | R58: =K58+M58+Q58 -> 0 | S58: =R58*5% -> 0 | T58: =R58+S58 -> 0 | U58: 22.10.20 SAMPLE SENT
A59: 484 | B59: 23.10.20 | C59: 57 | D59: 56 | E59: 161000645 | F59: 59 | G59: 3561.22 | H59: 272.78 | I59: 0 | J59: 0 | K59: 0 | L59: 0 | M59: 0 | N59: 0 | O59: 0 | P59: 0 | Q59: 0 | R59: =K59+M59+Q59 -> 0 | S59: =R59*5% -> 0 | T59: =R59+S59 -> 0
A60: 485 | B60: 23.10.20 | C60: 58 | D60: 57 | E60: 161000646 | F60: 57 | G60: 3433.43 | H60: 271.57 | I60: 0 | J60: 0 | K60: 0 | L60: 0 | M60: 0 | N60: 0 | O60: 0 | P60: 0 | Q60: 0 | R60: =K60+M60+Q60 -> 0 | S60: =R60*5% -> 0 | T60: =R60+S60 -> 0
A61: 486 | B61: 23.10.20 | C61: 59 | D61: 58 | E61: 161000647 | F61: 58 | G61: 3474.03 | H61: 294.97 | I61: 0 | J61: 0 | K61: 0 | L61: 0 | M61: 0 | N61: 0 | O61: 0 | P61: 0 | Q61: 0 | R61: =K61+M61+Q61 -> 0 | S61: =R61*5% -> 0 | T61: =R61+S61 -> 0
A62: 487 | B62: 23.10.20 | C62: 60 | D62: 59 | E62: 161000648 | F62: 58 | G62: 3473.02 | H62: 296.98 | I62: 0 | J62: 0 | K62: 0 | L62: 0 | M62: 0 | N62: 0 | O62: 0 | P62: 0 | Q62: 0 | R62: =K62+M62+Q62 -> 0 | S62: =R62*5% -> 0 | T62: =R62+S62 -> 0
A63: 488 | B63: 24.10.20 | C63: 61 | D63: 60 | E63: 161000649 | F63: 59 | G63: 3549.22 | H63: 284.78 | I63: 0 | J63: 0 | K63: 0 | L63: 0 | M63: 0 | N63: 0 | O63: 0 | P63: 0 | Q63: 0 | R63: =K63+M63+Q63 -> 0 | S63: =R63*5% -> 0 | T63: =R63+S63 -> 0
A64: 489 | B64: 24.10.20 | C64: 62 | D64: 61 | E64: 161000650 | F64: 58 | G64: 3401.03 | H64: 367.97 | I64: 0 | J64: 0 | K64: 0 | L64: 0 | M64: 0 | N64: 0 | O64: 0 | P64: 0 | Q64: 0 | R64: =K64+M64+Q64 -> 0 | S64: =R64*5% -> 0 | T64: =R64+S64 -> 0
A65: 490 | B65: 25.10.20 | C65: 63 | D65: 62 | E65: 161000651 | F65: 59 | G65: 3561.44 | H65: 270.56 | I65: 0 | J65: 0 | K65: 0 | L65: 0 | M65: 0 | N65: 0 | O65: 0 | P65: 0 | Q65: 0 | R65: =K65+M65+Q65 -> 0 | S65: =R65*5% -> 0 | T65: =R65+S65 -> 0
A66: 491 | B66: 25.10.20 | C66: 64 | D66: 63 | E66: 162000016 | F66: 58 | G66: 3503.33 | H66: 255.67 | I66: 0 | J66: 0 | K66: 0 | L66: 0 | M66: 0 | N66: 0 | O66: 0 | P66: 0 | Q66: 0 | R66: =K66+M66+Q66 -> 0 | S66: =R66*5% -> 0 | T66: =R66+S66 -> 0
A67: 492 | B67: 26.10.20 | C67: 65 | D67: 64 | E67: 161000652 | F67: 59 | G67: 3583.62 | H67: 250.38 | I67: 0 | J67: 0 | K67: 0 | L67: 0 | M67: 0 | N67: 0 | O67: 0 | P67: 0 | Q67: 0 | R67: =K67+M67+Q67 -> 0 | S67: =R67*5% -> 0 | T67: =R67+S67 -> 0
A68: 493 | B68: 26.10.20 | C68: 66 | D68: 65 | E68: 161000653 | F68: 55 | G68: 3331.91 | H68: 237.09 | I68: 0 | J68: 0 | K68: 0 | L68: 0 | M68: 0 | N68: 0 | O68: 0 | P68: 0 | Q68: 0 | R68: =K68+M68+Q68 -> 0 | S68: =R68*5% -> 0 | T68: =R68+S68 -> 0
...

Sheet NOV
A1: NOVEMBER MONTH RAKE LOADING DATA
A2: SL NO | B2: LOADING DATE | C2: RAKE NO. | D2: PRIORTY NUMBER | E2: R.R NUMBER | F2: NO OF WAGON | G2: NET WEIGHT | H2: UNDER LOAD WT | I2: OVER LOAD WT | J2: O/L WAGON | K2: O/L CHARGE | L2: DETENTION HOURS | M2: DETENTION CHARGES | N2: SHUNTING HOURS | O2: SHUNTING CHARGES | P2: PILOT HOURS | Q2: PILOT CHARGES | R2: PCLA | S2: GST 5% | T2: TOTAL AMOUNT RS | U2: RESULT DATE
A3: 525 | B3: 01.11.20 | C3: 1 | D3: 97 | E3: 161000680 | F3: 58 | G3: 3526.43 | H3: 242.57 | I3: 0 | J3: 0 | K3: 0 | L3: 0 | M3: 0 | N3: 0 | O3: 0 | P3: 0 | Q3: 0 | R3: =K3+M3+Q3 -> 0 | S3: =R3*5% -> 0 | T3: =R3+S3 -> 0
A4: 526 | B4: 01.11.20 | C4: 2 | D4: 98 | E4: 161000681 | F4: 59 | G4: 3589.64 | H4: 242.36 | I4: 0 | J4: 0 | K4: 0 | L4: 0 | M4: 0 | N4: 0 | O4: 0 | P4: 0 | Q4: 0 | R4: =K4+M4+Q4 -> 0 | S4: =R4*5% -> 0 | T4: =R4+S4 -> 0
A5: 527 | B5: 01.11.20 | C5: 3 | D5: 99 | E5: 162000022 | F5: 59 | G5: 3592.42 | H5: 241.58 | I5: 0 | J5: 0 | K5: 0 | L5: 0 | M5: 0 | N5: 0 | O5: 0 | P5: 0 | Q5: 0 | R5: =K5+M5+Q5 -> 0 | S5: =R5*5% -> 0 | T5: =R5+S5 -> 0
A6: 528 | B6: 01.11.20 | C6: 4 | D6: 100 | E6: 161000682 | F6: 59 | G6: 3570.84 | H6: 261.16 | I6: 0 | J6: 0 | K6: 0 | L6: 0 | M6: 0 | N6: 0 | O6: 0 | P6: 0 | Q6: 0 | R6: =K6+M6+Q6 -> 0 | S6: =R6*5% -> 0 | T6: =R6+S6 -> 0
A7: 529 | B7: 01.11.20 | C7: 5 | D7: 101 | E7: 161000683 | F7: 58 | G7: 3429.04 | H7: 338.96 | I7: 0 | J7: 0 | K7: 0 | L7: 0 | M7: 0 | N7: 0 | O7: 0 | P7: 0 | Q7: 0 | R7: =K7+M7+Q7 -> 0 | S7: =R7*5% -> 0 | T7: =R7+S7 -> 0
A8: 530 | B8: 02.11.20 | C8: 6 | D8: 102 | E8: 161000684 | F8: 57 | G8: 3393.48 | H8: 306.52 | I8: 0 | J8: 0 | K8: 0 | L8: 0 | M8: 0 | N8: 0 | O8: 0 | P8: 0 | Q8: 0 | R8: =K8+M8+Q8 -> 0 | S8: =R8*5% -> 0 | T8: =R8+S8 -> 0
A9: 531 | B9: 02.11.20 | C9: 7 | D9: 103 | E9: 161000685 | F9: 58 | G9: 3492.62 | H9: 277.38 | I9: 0 | J9: 0 | K9: 0 | L9: 0 | M9: 0 | N9: 0 | O9: 0 | P9: 0 | Q9: 0 | R9: =K9+M9+Q9 -> 0 | S9: =R9*5% -> 0 | T9: =R9+S9 -> 0
A10: 532 | B10: 02.11.20 | C10: 8 | D10: 104 | E10: 162000023 | F10: 57 | G10: 3400.63 | H10: 304.37 | I10: 0 | J10: 0 | K10: 0 | L10: 0 | M10: 0 | N10: 0 | O10: 0 | P10: 0 | Q10: 0 | R10: =K10+M10+Q10 -> 0 | S10: =R10*5% -> 0 | T10: =R10+S10 -> 0
A11: 533 | B11: 02.11.20 | C11: 9 | D11: 105 | E11: 161000686 | F11: 59 | G11: 3500.04 | H11: 331.96 | I11: 0 | J11: 0 | K11: 0 | L11: 0 | M11: 0 | N11: 0 | O11: 0 | P11: 0 | Q11: 0 | R11: =K11+M11+Q11 -> 0 | S11: =R11*5% -> 0 | T11: =R11+S11 -> 0
A12: 534 | B12: 02.11.20 | C12: 10 | D12: 106 | E12: 161000687 | F12: 59 | G12: 3562.22 | H12: 271.78 | I12: 0 | J12: 0 | K12: 0 | L12: 0 | M12: 0 | N12: 0 | O12: 0 | P12: 0 | Q12: 0 | R12: =K12+M12+Q12 -> 0 | S12: =R12*5% -> 0 | T12: =R12+S12 -> 0
A13: 535 | B13: 02.11.20 | C13: 11 | D13: 107 | E13: 161000688 | F13: 59 | G13: 3492.22 | H13: 341.78 | I13: 0 | J13: 0 | K13: 0 | L13: 0 | M13: 0 | N13: 0 | O13: 0 | P13: 0 | Q13: 0 | R13: =K13+M13+Q13 -> 0 | S13: =R13*5% -> 0 | T13: =R13+S13 -> 0
A14: 536 | B14: 03.11.20 | C14: 12 | D14: 108 | E14: 161000689 | F14: 58 | G14: 3477.03 | H14: 291.97 | I14: 0 | J14: 0 | K14: 0 | L14: 0 | M14: 0 | N14: 0 | O14: 0 | P14: 0 | Q14: 0 | R14: =K14+M14+Q14 -> 0 | S14: =R14*5% -> 0 | T14: =R14+S14 -> 0
... A41: 563 | B41: 07.11.20 | C41: 39 | D41: 133 | E41: 161000708 | F41: 58 | G41: 3503.82 | H41: 266.18 | I41: 0 | J41: 0 | K41: 0 | L41: 0 | M41: 0 | N41: 0 | O41: 0 | P41: 0 | Q41: 0 | R41: =K41+M41+Q41 -> 0 | S41: =R41*5% -> 0 | T41: =R41+S41 -> 0
A42: 564 | B42: 07.11.20 | C42: 40 | D42: 135 | E42: 161000709 | F42: 58 | G42: 3503.46 | H42: 460.54 | I42: 0 | J42: 0 | K42: 0 | L42: 0 | M42: 0 | N42: 1 | O42: 0 | P42: 0 | Q42: 8700 | R42: =K42+M42+Q42 -> 8700 | S42: =R42*5% -> 435 | T42: =R42+S42 -> 9135 | V42: LOADING DELAY (ABOVE 3 HOURS)
A43: 565 | B43: 07.11.20 | C43: 41 | D43: 137 | E43: 161000710 | F43: 57 | G43: 3445.84 | H43: 258.16 | I43: 0 | J43: 0 | K43: 0 | L43: 0 | M43: 0 | N43: 0 | O43: 0 | P43: 0 | Q43: 0 | R43: =K43+M43+Q43 -> 0 | S43: =R43*5% -> 0 | T43: =R43+S43 -> 0
A44: 566 | B44: 07.11.20 | C44: 42 | D44: 138 | E44: 141000042 | F44: 59 | G44: 3578.61 | H44: 256.39 | I44: 0 | J44: 0 | K44: 0 | L44: 0 | M44: 0 | N44: 0 | O44: 0 | P44: 0 | Q44: 0 | R44: =K44+M44+Q44 -> 0 | S44: =R44*5% -> 0 | T44: =R44+S44 -> 0
A45: 567 | B45: 08.11.20 | C45: 43 | D45: 139 | E45: 161000711 | F45: 58 | G45: 3569.42 | H45: 200.58 | I45: 0 | J45: 0 | K45: 0 | L45: 0 | M45: 0 | N45: 0 | O45: 0 | P45: 0 | Q45: 0 | R45: =K45+M45+Q45 -> 0 | S45: =R45*5% -> 0 | T45: =R45+S45 -> 0
A46: 568 | B46: 08.11.20 | C46: 44 | D46: 140 | E46: 161000712 | F46: 59 | G46: 3618.42 | H46: 215.97 | I46: 0 | J46: 0 | K46: 0 | L46: 0 | M46: 0 | N46: 0 | O46: 0 | P46: 0 | Q46: 0 | R46: =K46+M46+Q46 -> 0 | S46: =R46*5% -> 0 | T46: =R46+S46 -> 0
A47: 569 | B47: 08.11.20 | C47: 45 | D47: 141 | E47: 151000022 | F47: 58 | G47: 3538.22 | H47: 232.17 | I47: 0 | J47: 0 | K47: 0 | L47: 0 | M47: 0 | N47: 0 | O47: 0 | P47: 0 | Q47: 0 | R47: =K47+M47+Q47 -> 0 | S47: =R47*5% -> 0 | T47: =R47+S47 -> 0
A48: 570 | B48: 08.11.20 | C48: 46 | D48: 142 | E48: 152000001 | F48: 59 | G48: 3596.02 | H48: 237.98 | I48: 0 | J48: 0 | K48: 0 | L48: 0 | M48: 0 | N48: 0 | O48: 0 | P48: 0 | Q48: 0 | R48: =K48+M48+Q48 -> 0 | S48: =R48*5% -> 0 | T48: =R48+S48 -> 0
A49: 571 | B49: 08.11.20 | C49: 47 | D49: 144 | E49: 151000023 | F49: 59 | G49: 3569.02 | H49: 264.98 | I49: 0 | J49: 0 | K49: 0 | L49: 0 | M49: 0 | N49: 0 | O49: 0 | P49: 0 | Q49: 0 | R49: =K49+M49+Q49 -> 0 | S49: =R49*5% -> 0 | T49: =R49+S49 -> 0
A50: 572 | B50: 09.11.20 | C50: 48 | D50: 143 | E50: 151000024 | F50: 59 | G50: 3575.03 | H50: 257.97 | I50: 0 | J50: 0 | K50: 0 | L50: 0 | M50: 0 | N50: 0 | O50: 0 | P50: 0 | Q50: 0 | R50: =K50+M50+Q50 -> 0 | S50: =R50*5% -> 0 | T50: =R50+S50 -> 0
A51: 573 | B51: 09.11.20 | C51: 49 | D51: 145 | E51: 151000025 | F51: 58 | G51: 3544.03 | H51: 224.97 | I51: 0 | J51: 0 | K51: 0 | L51: 0 | M51: 0 | N51: 0 | O51: 0 | P51: 0 | Q51: 0 | R51: =K51+M51+Q51 -> 0 | S51: =R51*5% -> 0 | T51: =R51+S51 -> 0
A52: 574 | B52: 09.11.20 | C52: 50 | D52: 146 | E52: 152000002 | F52: 58 | G52: 3491.03 | H52: 277.97 | I52: 0 | J52: 0 | K52: 0 | L52: 0 | M52: 0 | N52: 0 | O52: 0 | P52: 0 | Q52: 0 | R52: =K52+M52+Q52 -> 0 | S52: =R52*5% -> 0 | T52: =R52+S52 -> 0
A53: 575 | B53: 09.11.20 | C53: 51 | D53: 147 | E53: 161000713 | F53: 58 | G53: 3533.63 | H53: 235.37 | I53: 0 | J53: 0 | K53: 0 | L53: 0 | M53: 0 | N53: 0 | O53: 0 | P53: 0 | Q53: 0 | R53: =K53+M53+Q53 -> 0 | S53: =R53*5% -> 0 | T53: =R53+S53 -> 0
A54: 576 | B54: 09.11.20 | C54: 52 | D54: 149 | E54: 161000714 | F54: 59 | G54: 3608.82 | H54: 225.37 | I54: 0 | J54: 0 | K54: 0 | L54: 0 | M54: 0 | N54: 0 | O54: 0 | P54: 0 | Q54: 0 | R54: =K54+M54+Q54 -> 0 | S54: =R54*5% -> 0 | T54: =R54+S54 -> 0
... A61: 583 | B61: 10.11.20 | C61: 59 | D61: 155 | E61: 162000033 | F61: 57 | G61: 3415.23 | H61: 289.77 | I61: 0 | J61: 0 | K61: 0 | L61: 0 | M61: 0 | N61: 0 | O61: 0 | P61: 0 | Q61: 0 | R61: =K61+M61+Q61 -> 0 | S61: =R61*5% -> 0 | T61: =R61+S61 -> 0
A62: 584 | B62: 11.11.20 | C62: 60 | D62: 156 | E62: 161000720 | F62: 59 | G62: 3524.61 | H62: 310.39 | I62: 0 | J62: 0 | K62: 0 | L62: 0 | M62: 0 | N62: 0 | O62: 0 | P62: 0 | Q62: 0 | R62: =K62+M62+Q62 -> 0 | S62: =R62*5% -> 0 | T62: =R62+S62 -> 0 | U62: 08.12.20
A63: 585 | B63: 11.11.20 | C63: 61 | D63: 158 | E63: 162000034 | F63: 58 | G63: 3480.63 | H63: 288.37 | I63: 0 | J63: 0 | K63: 0 | L63: 0 | M63: 0 | N63: 0 | O63: 0 | P63: 0 | Q63: 0 | R63: =K63+M63+Q63 -> 0 | S63: =R63*5% -> 0 | T63: =R63+S63 -> 0
A64: 586 | B64: 11.11.20 | C64: 62 | D64: 157 | E64: 161000721 | F64: 58 | G64: 3519.42 | H64: 250.58 | I64: 0 | J64: 0 | K64: 0 | L64: 0 | M64: 0 | N64: 0 | O64: 0 | P64: 0 | Q64: 0 | R64: =K64+M64+Q64 -> 0 | S64: =R64*5% -> 0 | T64: =R64+S64 -> 0 | U64: 08.12.20
A65: 587 | B65: 11.11.20 | C65: 63 | D65: 159 | E65: 161000722 | F65: 58 | G65: 3481.43 | H65: 287.57 | I65: 0 | J65: 0 | K65: 0 | L65: 0 | M65: 0 | N65: 0 | O65: 0 | P65: 0 | Q65: 0 | R65: =K65+M65+Q65 -> 0 | S65: =R65*5% -> 0 | T65: =R65+S65 -> 0 | U65: 04.12.20
A66: 588 | B66: 11.11.20 | C66: 64 | D66: 161 | E66: 151000026 | F66: 59 | G66: 3570.04 | H66: 261.96 | I66: 0 | J66: 0 | K66: 0 | L66: 0 | M66: 0 | N66: 0 | O66: 0 | P66: 0 | Q66: 0 | R66: =K66+M66+Q66 -> 0 | S66: =R66*5% -> 0 | T66: =R66+S66 -> 0 | U66: 08.12.20
A67: 589 | B67: 11.11.20 | C67: 65 | D67: 160 | E67: 161000723 | F67: 54 | G67: 3277.69 | H67: 229.31 | I67: 0 | J67: 0 | K67: 0 | L67: 0 | M67: 0 | N67: 0 | O67: 0 | P67: 0 | Q67: 0 | R67: =K67+M67+Q67 -> 0 | S67: =R67*5% -> 0 | T67: =R67+S67 -> 0 | U67: 04.12.20
A68: 590 | B68: 11.11.20 | C68: 66 | D68: 162 | E68: 162000035 | F68: 59 | G68: 3569.23 | H68: 263.77 | I68: 0 | J68: 0 | K68: 0 | L68: 0 | M68: 0 | N68: 0 | O68: 0 | P68: 0 | Q68: 0 | R68: =K68+M68+Q68 -> 0 | S68: =R68*5% -> 0 | T68: =R68+S68 -> 0
